Workbook
Name CONTROL_PESOS: #REF!
Name TABLA_CAPACIDAD: #REF!
Name TABLA_PESOS: #REF!
Name TABLA_PUREZA: #REF!

Sheet Lotes
A1: ID_Lote | B1: Fecha | C1: Semana | D1: Mes | E1: Tipo_fibra | F1: Turno | G1: Operador_ID | H1: Volumen_kg | J1: Tipo de fibra | K1: Turno | L1: Operador ID
A2: RETEX-2024-001 | B2: 46095 | C2: =WEEKNUM(B2,2) -> 11 | D2: =TEXT(B2,"mmmm") -> marzo | E2: Algodón | F2: =CHOOSE(MOD(ROW()-2,3)+1,"Matutino","Vespertino","Nocturno") -> Matutino | G2: =CHOOSE(RANDBETWEEN(1,6),"OP-01","OP-02","OP-03","OP-04","OP-05","OP-06") -> OP-06 | H2: 195.86 | J2: Algodón | K2: Matutino | L2: OP-01
A3: RETEX-2024-002 | B3: 46102 | C3: =WEEKNUM(B3,2) -> 12 | D3: =TEXT(B3,"mmmm") -> marzo | E3: Poliéster | F3: =CHOOSE(MOD(ROW()-2,3)+1,"Matutino","Vespertino","Nocturno") -> Vespertino | G3: =CHOOSE(RANDBETWEEN(1,6),"OP-01","OP-02","OP-03","OP-04","OP-05","OP-06") -> OP-04 | H3: 192.72 | J3: Poliéster | K3: Vespertino | L3: OP-02
A4: RETEX-2024-003 | B4: 46109 | C4: =WEEKNUM(B4,2) -> 13 | D4: =TEXT(B4,"mmmm") -> marzo | E4: Mezcla | F4: =CHOOSE(MOD(ROW()-2,3)+1,"Matutino","Vespertino","Nocturno") -> Nocturno | G4: =CHOOSE(RANDBETWEEN(1,6),"OP-01","OP-02","OP-03","OP-04","OP-05","OP-06") -> OP-03 | H4: 194.27 | J4: Mezcla | K4: Nocturno | L4: OP-03
A5: RETEX-2024-004 | B5: 46116 | C5: =WEEKNUM(B5,2) -> 14 | D5: =TEXT(B5,"mmmm") -> abril | E5: Algodón | F5: =CHOOSE(MOD(ROW()-2,3)+1,"Matutino","Vespertino","Nocturno") -> Matutino | G5: =CHOOSE(RANDBETWEEN(1,6),"OP-01","OP-02","OP-03","OP-04","OP-05","OP-06") -> OP-02 | H5: 194.85 | L5: OP-04
A6: RETEX-2024-005 | B6: 46123 | C6: =WEEKNUM(B6,2) -> 15 | D6: =TEXT(B6,"mmmm") -> abril | E6: Poliéster | F6: =CHOOSE(MOD(ROW()-2,3)+1,"Matutino","Vespertino","Nocturno") -> Vespertino | G6: =CHOOSE(RANDBETWEEN(1,6),"OP-01","OP-02","OP-03","OP-04","OP-05","OP-06") -> OP-06 | H6: 192.42 | L6: OP-05
A7: RETEX-2024-006 | B7: 46130 | C7: =WEEKNUM(B7,2) -> 16 | D7: =TEXT(B7,"mmmm") -> abril | E7: Mezcla | F7: =CHOOSE(MOD(ROW()-2,3)+1,"Matutino","Vespertino","Nocturno") -> Nocturno | G7: =CHOOSE(RANDBETWEEN(1,6),"OP-01","OP-02","OP-03","OP-04","OP-05","OP-06") -> OP-03 | H7: 192.8 | L7: OP-06
A8: RETEX-2024-007 | B8: 46137 | C8: =WEEKNUM(B8,2) -> 17 | D8: =TEXT(B8,"mmmm") -> abril | E8: Algodón | F8: =CHOOSE(MOD(ROW()-2,3)+1,"Matutino","Vespertino","Nocturno") -> Matutino | G8: =CHOOSE(RANDBETWEEN(1,6),"OP-01","OP-02","OP-03","OP-04","OP-05","OP-06") -> OP-05 | H8: 191.8
A9: RETEX-2024-008 | B9: 46144 | C9: =WEEKNUM(B9,2) -> 18 | D9: =TEXT(B9,"mmmm") -> mayo | E9: Poliéster | F9: =CHOOSE(MOD(ROW()-2,3)+1,"Matutino","Vespertino","Nocturno") -> Vespertino | G9: =CHOOSE(RANDBETWEEN(1,6),"OP-01","OP-02","OP-03","OP-04","OP-05","OP-06") -> OP-05 | H9: 194.19
A10: RETEX-2024-009 | B10: 46151 | C10: =WEEKNUM(B10,2) -> 19 | D10: =TEXT(B10,"mmmm") -> mayo | E10: Mezcla | F10: =CHOOSE(MOD(ROW()-2,3)+1,"Matutino","Vespertino","Nocturno") -> Nocturno | G10: =CHOOSE(RANDBETWEEN(1,6),"OP-01","OP-02","OP-03","OP-04","OP-05","OP-06") -> OP-02 | H10: 196.5
A11: RETEX-2024-010 | B11: 46158 | C11: =WEEKNUM(B11,2) -> 20 | D11: =TEXT(B11,"mmmm") -> mayo | E11: Algodón | F11: =CHOOSE(MOD(ROW()-2,3)+1,"Matutino","Vespertino","Nocturno") -> Matutino | G11: =CHOOSE(RANDBETWEEN(1,6),"OP-01","OP-02","OP-03","OP-04","OP-05","OP-06") -> OP-04 | H11: 195.04
A12: RETEX-2024-011 | B12: 46165 | C12: =WEEKNUM(B12,2) -> 21 | D12: =TEXT(B12,"mmmm") -> mayo | E12: Poliéster | F12: =CHOOSE(MOD(ROW()-2,3)+1,"Matutino","Vespertino","Nocturno") -> Vespertino | G12: =CHOOSE(RANDBETWEEN(1,6),"OP-01","OP-02","OP-03","OP-04","OP-05","OP-06") -> OP-02 | H12: 194.34
A13: RETEX-2024-012 | B13: 46172 | C13: =WEEKNUM(B13,2) -> 22 | D13: =TEXT(B13,"mmmm") -> mayo | E13: Mezcla | F13: =CHOOSE(MOD(ROW()-2,3)+1,"Matutino","Vespertino","Nocturno") -> Nocturno | G13: =CHOOSE(RANDBETWEEN(1,6),"OP-01","OP-02","OP-03","OP-04","OP-05","OP-06") -> OP-02 | H13: 194.01
A14: RETEX-2024-013 | B14: 46179 | C14: =WEEKNUM(B14,2) -> 23 | D14: =TEXT(B14,"mmmm") -> junio | E14: Algodón | F14: =CHOOSE(MOD(ROW()-2,3)+1,"Matutino","Vespertino","Nocturno") -> Matutino | G14: =CHOOSE(RANDBETWEEN(1,6),"OP-01","OP-02","OP-03","OP-04","OP-05","OP-06") -> OP-01 | H14: 195.51
A15: RETEX-2024-014 | B15: 46186 | C15: =WEEKNUM(B15,2) -> 24 | D15: =TEXT(B15,"mmmm") -> junio | E15: Poliéster | F15: =CHOOSE(MOD(ROW()-2,3)+1,"Matutino","Vespertino","Nocturno") -> Vespertino | G15: =CHOOSE(RANDBETWEEN(1,6),"OP-01","OP-02","OP-03","OP-04","OP-05","OP-06") -> OP-05 | H15: 193.27
A16: RETEX-2024-015 | B16: 46193 | C16: =WEEKNUM(B16,2) -> 25 | D16: =TEXT(B16,"mmmm") -> junio | E16: Mezcla | F16: =CHOOSE(MOD(ROW()-2,3)+1,"Matutino","Vespertino","Nocturno") -> Nocturno | G16: =CHOOSE(RANDBETWEEN(1,6),"OP-01","OP-02","OP-03","OP-04","OP-05","OP-06") -> OP-06 | H16: 193.51
A17: RETEX-2024-016 | B17: 46200 | C17: =WEEKNUM(B17,2) -> 26 | D17: =TEXT(B17,"mmmm") -> junio | E17: Algodón | F17: =CHOOSE(MOD(ROW()-2,3)+1,"Matutino","Vespertino","Nocturno") -> Matutino | G17: =CHOOSE(RANDBETWEEN(1,6),"OP-01","OP-02","OP-03","OP-04","OP-05","OP-06") -> OP-01 | H17: 196.28
A18: RETEX-2024-017 | B18: 46207 | C18: =WEEKNUM(B18,2) -> 27 | D18: =TEXT(B18,"mmmm") -> julio | E18: Poliéster | F18: =CHOOSE(MOD(ROW()-2,3)+1,"Matutino","Vespertino","Nocturno") -> Vespertino | G18: =CHOOSE(RANDBETWEEN(1,6),"OP-01","OP-02","OP-03","OP-04","OP-05","OP-06") -> OP-04 | H18: 195.64
A19: RETEX-2024-018 | B19: 46214 | C19: =WEEKNUM(B19,2) -> 28 | D19: =TEXT(B19,"mmmm") -> julio | E19: Mezcla | F19: =CHOOSE(MOD(ROW()-2,3)+1,"Matutino","Vespertino","Nocturno") -> Nocturno | G19: =CHOOSE(RANDBETWEEN(1,6),"OP-01","OP-02","OP-03","OP-04","OP-05","OP-06") -> OP-03 | H19: 191.98
... A24: RETEX-2024-023 | B24: 46249 | C24: =WEEKNUM(B24,2) -> 33 | D24: =TEXT(B24,"mmmm") -> agosto | E24: Poliéster | F24: =CHOOSE(MOD(ROW()-2,3)+1,"Matutino","Vespertino","Nocturno") -> Vespertino | G24: =CHOOSE(RANDBETWEEN(1,6),"OP-01","OP-02","OP-03","OP-04","OP-05","OP-06") -> OP-02 | H24: 195.91
A25: RETEX-2024-024 | B25: 46256 | C25: =WEEKNUM(B25,2) -> 34 | D25: =TEXT(B25,"mmmm") -> agosto | E25: Mezcla | F25: =CHOOSE(MOD(ROW()-2,3)+1,"Matutino","Vespertino","Nocturno") -> Nocturno | G25: OP-04 | H25: 194.45
A26: RETEX-2024-025 | B26: 46263 | C26: =WEEKNUM(B26,2) -> 35 | D26: =TEXT(B26,"mmmm") -> agosto | E26: Algodón | F26: =CHOOSE(MOD(ROW()-2,3)+1,"Matutino","Vespertino","Nocturno") -> Matutino | G26: OP-03 | H26: 193.52
A27: RETEX-2024-026 | B27: 46270 | C27: =WEEKNUM(B27,2) -> 36 | D27: =TEXT(B27,"mmmm") -> septiembre | E27: Poliéster | F27: =CHOOSE(MOD(ROW()-2,3)+1,"Matutino","Vespertino","Nocturno") -> Vespertino | G27: OP-05 | H27: 195.18
A28: RETEX-2024-027 | B28: 46277 | C28: =WEEKNUM(B28,2) -> 37 | D28: =TEXT(B28,"mmmm") -> septiembre | E28: Mezcla | F28: =CHOOSE(MOD(ROW()-2,3)+1,"Matutino","Vespertino","Nocturno") -> Nocturno | G28: OP-06 | H28: 193.13
A29: RETEX-2024-028 | B29: 46284 | C29: =WEEKNUM(B29,2) -> 38 | D29: =TEXT(B29,"mmmm") -> septiembre | E29: Algodón | F29: =CHOOSE(MOD(ROW()-2,3)+1,"Matutino","Vespertino","Nocturno") -> Matutino | G29: OP-04 | H29: 193.9
A30: RETEX-2024-029 | B30: 46291 | C30: =WEEKNUM(B30,2) -> 39 | D30: =TEXT(B30,"mmmm") -> septiembre | E30: Poliéster | F30: =CHOOSE(MOD(ROW()-2,3)+1,"Matutino","Vespertino","Nocturno") -> Vespertino | G30: OP-04 | H30: 196.02
A31: RETEX-2024-030 | B31: 46298 | C31: =WEEKNUM(B31,2) -> 40 | D31: =TEXT(B31,"mmmm") -> octubre | E31: Mezcla | F31: =CHOOSE(MOD(ROW()-2,3)+1,"Matutino","Vespertino","Nocturno") -> Nocturno | G31: OP-06 | H31: 198.33
A32: RETEX-2024-031 | B32: 46305 | C32: =WEEKNUM(B32,2) -> 41 | D32: =TEXT(B32,"mmmm") -> octubre | E32: Algodón | F32: =CHOOSE(MOD(ROW()-2,3)+1,"Matutino","Vespertino","Nocturno") -> Matutino | G32: OP-06 | H32: 195.17
A33: RETEX-2024-032 | B33: 46312 | C33: =WEEKNUM(B33,2) -> 42 | D33: =TEXT(B33,"mmmm") -> octubre | E33: Poliéster | F33: =CHOOSE(MOD(ROW()-2,3)+1,"Matutino","Vespertino","Nocturno") -> Vespertino | G33: OP-03 | H33: 195.7
A34: RETEX-2024-033 | B34: 46319 | C34: =WEEKNUM(B34,2) -> 43 | D34: =TEXT(B34,"mmmm") -> octubre | E34: Mezcla | F34: =CHOOSE(MOD(ROW()-2,3)+1,"Matutino","Vespertino","Nocturno") -> Nocturno | G34: OP-04 | H34: 194.41
A35: RETEX-2024-034 | B35: 46326 | C35: =WEEKNUM(B35,2) -> 44 | D35: =TEXT(B35,"mmmm") -> octubre | E35: Algodón | F35: =CHOOSE(MOD(ROW()-2,3)+1,"Matutino","Vespertino","Nocturno") -> Matutino | G35: OP-05 | H35: 199.25
A36: RETEX-2024-035 | B36: 46333 | C36: =WEEKNUM(B36,2) -> 45 | D36: =TEXT(B36,"mmmm") -> noviembre | E36: Poliéster | F36: =CHOOSE(MOD(ROW()-2,3)+1,"Matutino","Vespertino","Nocturno") -> Vespertino | G36: OP-04 | H36: 195.72
... A53: RETEX-2024-052 | B53: 46452 | C53: =WEEKNUM(B53,2) -> 10 | D53: =TEXT(B53,"mmmm") -> marzo | E53: Algodón | F53: =CHOOSE(MOD(ROW()-2,3)+1,"Matutino","Vespertino","Nocturno") -> Matutino | G53: OP-06 | H53: 196.59

Sheet Mediciones_Pureza
A1: ID_Medicion | B1: ID_Lote | C1: Fecha | D1: Semana | E1: Tipo_fibra | F1: Pureza_% | G1: LI | H1: LS | I1: Resultado | J1: Media_Acumulada | K1: Sigma_Acumulada | L1: Cp_Acumulado | M1: Cpk_Acumulado | N1: Estado_proceso | O1: Desviacion_vs_Media
A2: ="MED-"&TEXT(ROW()-1,"000") -> MED-001 | B2: =INDEX(Lotes!$A$2:$A$53,INT((ROW()-2)/5)+1) -> RETEX-2024-001 | C2: =INDEX(Lotes!$B$2:$B$53,INT((ROW()-2)/5)+1) -> 46095 | D2: =INDEX(Lotes!$C$2:$C$53,INT((ROW()-2)/5)+1) -> 11 | E2: =INDEX(Lotes!$E$2:$E$53,INT((ROW()-2)/5)+1) -> Algodón | F2: 98.14 | G2: =96 -> 96 | H2: =100 -> 100 | I2: =IF(F2<G2,"❌ NOK - Bajo límite",IF(F2>H2,"❌ NOK - Sobre límite","✅ OK")) -> ✅ OK | J2: =AVERAGE($F$2:F2) -> 98.14 | K2: =IF(COUNTA($F$2:F2)<20,"",_xlfn.STDEV.P($F$2:F2)) | L2: =IF(K2="","",ROUND((H2-G2)/(6*K2),2)) | M2: =IF(K2="","",ROUND(MIN((H2-J2)/(3*K2),(J2-G2)/(3*K2)),2)) | N2: =IF(M2="","⏳ Acumulando datos", IF(M2>=1.33,"✅ CAPAZ", IF(M2>=1,"⚠️ MARGINAL", IF(M2>=0.67,"❌ NO CAPAZ — Requiere mejora", "🚨 CRÍTICO — Acción inmediata")))) -> ⏳ Acumulando datos | O2: =IF(J3="","",ROUND(F3-J3,2)) -> 0.53
A3: ="MED-"&TEXT(ROW()-1,"000") -> MED-002 | B3: =INDEX(Lotes!$A$2:$A$53,INT((ROW()-2)/5)+1) -> RETEX-2024-001 | C3: =INDEX(Lotes!$B$2:$B$53,INT((ROW()-2)/5)+1) -> 46095 | D3: =INDEX(Lotes!$C$2:$C$53,INT((ROW()-2)/5)+1) -> 11 | E3: =INDEX(Lotes!$E$2:$E$53,INT((ROW()-2)/5)+1) -> Algodón | F3: 99.2 | G3: =96 -> 96 | H3: =100 -> 100 | I3: =IF(F3<G3,"❌ NOK - Bajo límite",IF(F3>H3,"❌ NOK - Sobre límite","✅ OK")) -> ✅ OK | J3: =AVERAGE($F$2:F3) -> 98.67 | K3: =IF(COUNTA($F$2:F3)<20,"",_xlfn.STDEV.P($F$2:F3)) | L3: =IF(K3="","",ROUND((H3-G3)/(6*K3),2)) | M3: =IF(K3="","",ROUND(MIN((H3-J3)/(3*K3),(J3-G3)/(3*K3)),2)) | N3: =IF(M3="","⏳ Acumulando datos", IF(M3>=1.33,"✅ CAPAZ", IF(M3>=1,"⚠️ MARGINAL", IF(M3>=0.67,"❌ NO CAPAZ — Requiere mejora", "🚨 CRÍTICO — Acción inmediata")))) -> ⏳ Acumulando datos | O3: =IF(J4="","",ROUND(F4-J4,2)) -> -0.19
A4: ="MED-"&TEXT(ROW()-1,"000") -> MED-003 | B4: =INDEX(Lotes!$A$2:$A$53,INT((ROW()-2)/5)+1) -> RETEX-2024-001 | C4: =INDEX(Lotes!$B$2:$B$53,INT((ROW()-2)/5)+1) -> 46095 | D4: =INDEX(Lotes!$C$2:$C$53,INT((ROW()-2)/5)+1) -> 11 | E4: =INDEX(Lotes!$E$2:$E$53,INT((ROW()-2)/5)+1) -> Algodón | F4: 98.39 | G4: =96 -> 96 | H4: =100 -> 100 | I4: =IF(F4<G4,"❌ NOK - Bajo límite",IF(F4>H4,"❌ NOK - Sobre límite","✅ OK")) -> ✅ OK | J4: =AVERAGE($F$2:F4) -> 98.576667 | K4: =IF(COUNTA($F$2:F4)<20,"",_xlfn.STDEV.P($F$2:F4)) | L4: =IF(K4="","",ROUND((H4-G4)/(6*K4),2)) | M4: =IF(K4="","",ROUND(MIN((H4-J4)/(3*K4),(J4-G4)/(3*K4)),2)) | N4: =IF(M4="","⏳ Acumulando datos", IF(M4>=1.33,"✅ CAPAZ", IF(M4>=1,"⚠️ MARGINAL", IF(M4>=0.67,"❌ NO CAPAZ — Requiere mejora", "🚨 CRÍTICO — Acción inmediata")))) -> ⏳ Acumulando datos | O4: =IF(J5="","",ROUND(F5-J5,2)) -> 0.18
A5: ="MED-"&TEXT(ROW()-1,"000") -> MED-004 | B5: =INDEX(Lotes!$A$2:$A$53,INT((ROW()-2)/5)+1) -> RETEX-2024-001 | C5: =INDEX(Lotes!$B$2:$B$53,INT((ROW()-2)/5)+1) -> 46095 | D5: =INDEX(Lotes!$C$2:$C$53,INT((ROW()-2)/5)+1) -> 11 | E5: =INDEX(Lotes!$E$2:$E$53,INT((ROW()-2)/5)+1) -> Algodón | F5: 98.82 | G5: =96 -> 96 | H5: =100 -> 100 | I5: =IF(F5<G5,"❌ NOK - Bajo límite",IF(F5>H5,"❌ NOK - Sobre límite","✅ OK")) -> ✅ OK | J5: =AVERAGE($F$2:F5) -> 98.6375 | K5: =IF(COUNTA($F$2:F5)<20,"",_xlfn.STDEV.P($F$2:F5)) | L5: =IF(K5="","",ROUND((H5-G5)/(6*K5),2)) | M5: =IF(K5="","",ROUND(MIN((H5-J5)/(3*K5),(J5-G5)/(3*K5)),2)) | N5: =IF(M5="","⏳ Acumulando datos", IF(M5>=1.33,"✅ CAPAZ", IF(M5>=1,"⚠️ MARGINAL", IF(M5>=0.67,"❌ NO CAPAZ — Requiere mejora", "🚨 CRÍTICO — Acción inmediata")))) -> ⏳ Acumulando datos | O5: =IF(J6="","",ROUND(F6-J6,2)) -> -0.14
A6: ="MED-"&TEXT(ROW()-1,"000") -> MED-005 | B6: =INDEX(Lotes!$A$2:$A$53,INT((ROW()-2)/5)+1) -> RETEX-2024-001 | C6: =INDEX(Lotes!$B$2:$B$53,INT((ROW()-2)/5)+1) -> 46095 | D6: =INDEX(Lotes!$C$2:$C$53,INT((ROW()-2)/5)+1) -> 11 | E6: =INDEX(Lotes!$E$2:$E$53,INT((ROW()-2)/5)+1) -> Algodón | F6: 98.46 | G6: =96 -> 96 | H6: =100 -> 100 | I6: =IF(F6<G6,"❌ NOK - Bajo límite",IF(F6>H6,"❌ NOK - Sobre límite","✅ OK")) -> ✅ OK | J6: =AVERAGE($F$2:F6) -> 98.602 | K6: =IF(COUNTA($F$2:F6)<20,"",_xlfn.STDEV.P($F$2:F6)) | L6: =IF(K6="","",ROUND((H6-G6)/(6*K6),2)) | M6: =IF(K6="","",ROUND(MIN((H6-J6)/(3*K6),(J6-G6)/(3*K6)),2)) | N6: =IF(M6="","⏳ Acumulando datos", IF(M6>=1.33,"✅ CAPAZ", IF(M6>=1,"⚠️ MARGINAL", IF(M6>=0.67,"❌ NO CAPAZ — Requiere mejora", "🚨 CRÍTICO — Acción inmediata")))) -> ⏳ Acumulando datos | O6: =IF(J7="","",ROUND(F7-J7,2)) -> 0.19
A7: ="MED-"&TEXT(ROW()-1,"000") -> MED-006 | B7: =INDEX(Lotes!$A$2:$A$53,INT((ROW()-2)/5)+1) -> RETEX-2024-002 | C7: =INDEX(Lotes!$B$2:$B$53,INT((ROW()-2)/5)+1) -> 46102 | D7: =INDEX(Lotes!$C$2:$C$53,INT((ROW()-2)/5)+1) -> 12 | E7: =INDEX(Lotes!$E$2:$E$53,INT((ROW()-2)/5)+1) -> Poliéster | F7: 98.83 | G7: =96 -> 96 | H7: =100 -> 100 | I7: =IF(F7<G7,"❌ NOK - Bajo límite",IF(F7>H7,"❌ NOK - Sobre límite","✅ OK")) -> ✅ OK | J7: =AVERAGE($F$2:F7) -> 98.64 | K7: =IF(COUNTA($F$2:F7)<20,"",_xlfn.STDEV.P($F$2:F7)) | L7: =IF(K7="","",ROUND((H7-G7)/(6*K7),2)) | M7: =IF(K7="","",ROUND(MIN((H7-J7)/(3*K7),(J7-G7)/(3*K7)),2)) | N7: =IF(M7="","⏳ Acumulando datos", IF(M7>=1.33,"✅ CAPAZ", IF(M7>=1,"⚠️ MARGINAL", IF(M7>=0.67,"❌ NO CAPAZ — Requiere mejora", "🚨 CRÍTICO — Acción inmediata")))) -> ⏳ Acumulando datos | O7: =IF(J8="","",ROUND(F8-J8,2)) -> 0.17
A8: ="MED-"&TEXT(ROW()-1,"000") -> MED-007 | B8: =INDEX(Lotes!$A$2:$A$53,INT((ROW()-2)/5)+1) -> RETEX-2024-002 | C8: =INDEX(Lotes!$B$2:$B$53,INT((ROW()-2)/5)+1) -> 46102 | D8: =INDEX(Lotes!$C$2:$C$53,INT((ROW()-2)/5)+1) -> 12 | E8: =INDEX(Lotes!$E$2:$E$53,INT((ROW()-2)/5)+1) -> Poliéster | F8: 98.84 | G8: =96 -> 96 | H8: =100 -> 100 | I8: =IF(F8<G8,"❌ NOK - Bajo límite",IF(F8>H8,"❌ NOK - Sobre límite","✅ OK")) -> ✅ OK | J8: =AVERAGE($F$2:F8) -> 98.668571 | K8: =IF(COUNTA($F$2:F8)<20,"",_xlfn.STDEV.P($F$2:F8)) | L8: =IF(K8="","",ROUND((H8-G8)/(6*K8),2)) | M8: =IF(K8="","",ROUND(MIN((H8-J8)/(3*K8),(J8-G8)/(3*K8)),2)) | N8: =IF(M8="","⏳ Acumulando datos", IF(M8>=1.33,"✅ CAPAZ", IF(M8>=1,"⚠️ MARGINAL", IF(M8>=0.67,"❌ NO CAPAZ — Requiere mejora", "🚨 CRÍTICO — Acción inmediata")))) -> ⏳ Acumulando datos | O8: =IF(J9="","",ROUND(F9-J9,2)) -> 0.81
A9: ="MED-"&TEXT(ROW()-1,"000") -> MED-008 | B9: =INDEX(Lotes!$A$2:$A$53,INT((ROW()-2)/5)+1) -> RETEX-2024-002 | C9: =INDEX(Lotes!$B$2:$B$53,INT((ROW()-2)/5)+1) -> 46102 | D9: =INDEX(Lotes!$C$2:$C$53,INT((ROW()-2)/5)+1) -> 12 | E9: =INDEX(Lotes!$E$2:$E$53,INT((ROW()-2)/5)+1) -> Poliéster | F9: 99.6 | G9: =96 -> 96 | H9: =100 -> 100 | I9: =IF(F9<G9,"❌ NOK - Bajo límite",IF(F9>H9,"❌ NOK - Sobre límite","✅ OK")) -> ✅ OK | J9: =AVERAGE($F$2:F9) -> 98.785 | K9: =IF(COUNTA($F$2:F9)<20,"",_xlfn.STDEV.P($F$2:F9)) | L9: =IF(K9="","",ROUND((H9-G9)/(6*K9),2)) | M9: =IF(K9="","",ROUND(MIN((H9-J9)/(3*K9),(J9-G9)/(3*K9)),2)) | N9: =IF(M9="","⏳ Acumulando datos", IF(M9>=1.33,"✅ CAPAZ", IF(M9>=1,"⚠️ MARGINAL", IF(M9>=0.67,"❌ NO CAPAZ — Requiere mejora", "🚨 CRÍTICO — Acción inmediata")))) -> ⏳ Acumulando datos | O9: =IF(J10="","",ROUND(F10-J10,2)) -> -0.08
A10: ="MED-"&TEXT(ROW()-1,"000") -> MED-009 | B10: =INDEX(Lotes!$A$2:$A$53,INT((ROW()-2)/5)+1) -> RETEX-2024-002 | C10: =INDEX(Lotes!$B$2:$B$53,INT((ROW()-2)/5)+1) -> 46102 | D10: =INDEX(Lotes!$C$2:$C$53,INT((ROW()-2)/5)+1) -> 12 | E10: =INDEX(Lotes!$E$2:$E$53,INT((ROW()-2)/5)+1) -> Poliéster | F10: 98.7 | G10: =96 -> 96 | H10: =100 -> 100 | I10: =IF(F10<G10,"❌ NOK - Bajo límite",IF(F10>H10,"❌ NOK - Sobre límite","✅ OK")) -> ✅ OK | J10: =AVERAGE($F$2:F10) -> 98.775556 | K10: =IF(COUNTA($F$2:F10)<20,"",_xlfn.STDEV.P($F$2:F10)) | L10: =IF(K10="","",ROUND((H10-G10)/(6*K10),2)) | M10: =IF(K10="","",ROUND(MIN((H10-J10)/(3*K10),(J10-G10)/(3*K10)),2)) | N10: =IF(M10="","⏳ Acumulando datos", IF(M10>=1.33,"✅ CAPAZ", IF(M10>=1,"⚠️ MARGINAL", IF(M10>=0.67,"❌ NO CAPAZ — Requiere mejora", "🚨 CRÍTICO — Acción inmediata")))) -> ⏳ Acumulando datos | O10: =IF(J11="","",ROUND(F11-J11,2)) -> -0.16
A11: ="MED-"&TEXT(ROW()-1,"000") -> MED-010 | B11: =INDEX(Lotes!$A$2:$A$53,INT((ROW()-2)/5)+1) -> RETEX-2024-002 | C11: =INDEX(Lotes!$B$2:$B$53,INT((ROW()-2)/5)+1) -> 46102 | D11: =INDEX(Lotes!$C$2:$C$53,INT((ROW()-2)/5)+1) -> 12 | E11: =INDEX(Lotes!$E$2:$E$53,INT((ROW()-2)/5)+1) -> Poliéster | F11: 98.6 | G11: =96 -> 96 | H11: =100 -> 100 | I11: =IF(F11<G11,"❌ NOK - Bajo límite",IF(F11>H11,"❌ NOK - Sobre límite","✅ OK")) -> ✅ OK | J11: =AVERAGE($F$2:F11) -> 98.758 | K11: =IF(COUNTA($F$2:F11)<20,"",_xlfn.STDEV.P($F$2:F11)) | L11: =IF(K11="","",ROUND((H11-G11)/(6*K11),2)) | M11: =IF(K11="","",ROUND(MIN((H11-J11)/(3*K11),(J11-G11)/(3*K11)),2)) | N11: =IF(M11="","⏳ Acumulando datos", IF(M11>=1.33,"✅ CAPAZ", IF(M11>=1,"⚠️ MARGINAL", IF(M11>=0.67,"❌ NO CAPAZ — Requiere mejora", "🚨 CRÍTICO — Acción inmediata")))) -> ⏳ Acumulando datos | O11: =IF(J12="","",ROUND(F12-J12,2)) -> -1.55
A12: ="MED-"&TEXT(ROW()-1,"000") -> MED-011 | B12: =INDEX(Lotes!$A$2:$A$53,INT((ROW()-2)/5)+1) -> RETEX-2024-003 | C12: =INDEX(Lotes!$B$2:$B$53,INT((ROW()-2)/5)+1) -> 46109 | D12: =INDEX(Lotes!$C$2:$C$53,INT((ROW()-2)/5)+1) -> 13 | E12: =INDEX(Lotes!$E$2:$E$53,INT((ROW()-2)/5)+1) -> Mezcla | F12: 97.05 | G12: =96 -> 96 | H12: =100 -> 100 | I12: =IF(F12<G12,"❌ NOK - Bajo límite",IF(F12>H12,"❌ NOK - Sobre límite","✅ OK")) -> ✅ OK | J12: =AVERAGE($F$2:F12) -> 98.602727 | K12: =IF(COUNTA($F$2:F12)<20,"",_xlfn.STDEV.P($F$2:F12)) | L12: =IF(K12="","",ROUND((H12-G12)/(6*K12),2)) | M12: =IF(K12="","",ROUND(MIN((H12-J12)/(3*K12),(J12-G12)/(3*K12)),2)) | N12: =IF(M12="","⏳ Acumulando datos", IF(M12>=1.33,"✅ CAPAZ", IF(M12>=1,"⚠️ MARGINAL", IF(M12>=0.67,"❌ NO CAPAZ — Requiere mejora", "🚨 CRÍTICO — Acción inmediata")))) -> ⏳ Acumulando datos | O12: =IF(J13="","",ROUND(F13-J13,2)) -> -1.95
A13: ="MED-"&TEXT(ROW()-1,"000") -> MED-012 | B13: =INDEX(Lotes!$A$2:$A$53,INT((ROW()-2)/5)+1) -> RETEX-2024-003 | C13: =INDEX(Lotes!$B$2:$B$53,INT((ROW()-2)/5)+1) -> 46109 | D13: =INDEX(Lotes!$C$2:$C$53,INT((ROW()-2)/5)+1) -> 13 | E13: =INDEX(Lotes!$E$2:$E$53,INT((ROW()-2)/5)+1) -> Mezcla | F13: 96.48 | G13: =96 -> 96 | H13: =100 -> 100 | I13: =IF(F13<G13,"❌ NOK - Bajo límite",IF(F13>H13,"❌ NOK - Sobre límite","✅ OK")) -> ✅ OK | J13: =AVERAGE($F$2:F13) -> 98.425833 | K13: =IF(COUNTA($F$2:F13)<20,"",_xlfn.STDEV.P($F$2:F13)) | L13: =IF(K13="","",ROUND((H13-G13)/(6*K13),2)) | M13: =IF(K13="","",ROUND(MIN((H13-J13)/(3*K13),(J13-G13)/(3*K13)),2)) | N13: =IF(M13="","⏳ Acumulando datos", IF(M13>=1.33,"✅ CAPAZ", IF(M13>=1,"⚠️ MARGINAL", IF(M13>=0.67,"❌ NO CAPAZ — Requiere mejora", "🚨 CRÍTICO — Acción inmediata")))) -> ⏳ Acumulando datos | O13: =IF(J14="","",ROUND(F14-J14,2)) -> 0.22
... A261: ="MED-"&TEXT(ROW()-1,"000") -> MED-260 | B261: =INDEX(Lotes!$A$2:$A$53,INT((ROW()-2)/5)+1) -> RETEX-2024-052 | C261: =INDEX(Lotes!$B$2:$B$53,INT((ROW()-2)/5)+1) -> 46452 | D261: =INDEX(Lotes!$C$2:$C$53,INT((ROW()-2)/5)+1) -> 10 | E261: =INDEX(Lotes!$E$2:$E$53,INT((ROW()-2)/5)+1) -> Algodón | F261: 97.75 | G261: =96 -> 96 | H261: =100 -> 100 | I261: =IF(F261<G261,"❌ NOK - Bajo límite",IF(F261>H261,"❌ NOK - Sobre límite","✅ OK")) -> ✅ OK | J261: =AVERAGE($F$2:F261) -> 98.228692 | K261: =IF(COUNTA($F$2:F261)<20,"",_xlfn.STDEV.P($F$2:F261)) -> 0.7672798 | L261: =IF(K261="","",ROUND((H261-G261)/(6*K261),2)) -> 0.87 | M261: =IF(K261="","",ROUND(MIN((H261-J261)/(3*K261),(J261-G261)/(3*K261)),2)) -> 0.77 | N261: =IF(M261="","⏳ Acumulando datos", IF(M261>=1.33,"✅ CAPAZ", IF(M261>=1,"⚠️ MARGINAL", IF(M261>=0.67,"❌ NO CAPAZ — Requiere mejora", "🚨 CRÍTICO — Acción inmediata")))) -> ❌ NO CAPAZ — Requiere mejora | O261: =IF(J262="","",ROUND(F262-J262,2))

Sheet Peso_Pacas
A1: ID_Subgrupo | B1: ID_Lote | C1: Fecha | D1: Semana | E1: Turno | F1: Num_Paca | G1: Peso_kg | H1: Media_Subgrupo | I1: Rango_Subgrupo | J1: LCS_Xbarra | K1: LCI_Xbarra | L1: Media_Medias | M1: Rango_Medio | N1: LCS_R | O1: LCI_R | P1: Señal_Xbarra | Q1: Señal_R
A2: ="SUB-"&TEXT(INT((ROW()-2)/5)+1,"000") -> SUB-001 | B2: =INDEX(Lotes!$A$2:$A$21,INT((ROW()-2)/5)+1) -> RETEX-2024-001 | C2: =INDEX(Lotes!$B$2:$B$21,INT((ROW()-2)/5)+1) -> 46095 | D2: =INDEX(Lotes!$C$2:$C$21,INT((ROW()-2)/5)+1) -> 11 | E2: =INDEX(Lotes!$F$2:$F$21,INT((ROW()-2)/5)+1) -> Matutino | F2: =MOD(ROW()-2,5)+1 -> 1 | G2: 194.9 | H2: =AVERAGE(INDEX($G$2:$G$101,INT((ROW()-2)/5)*5+1):INDEX($G$2:$G$101,INT((ROW()-2)/5)*5+5)) -> 194.086 | I2: =MAX(INDEX($G$2:$G$101,INT((ROW()-2)/5)*5+1):INDEX($G$2:$G$101,INT((ROW()-2)/5)*5+5))-MIN(INDEX($G$2:$G$101,INT((ROW()-2)/5)*5+1):INDEX($G$2:$G$101,INT((ROW()-2)/5)*5+5)) -> 4.13 | J2: =$L$2+(0.577*$M2) -> 198.01198 | K2: =$L2-(0.577*$M2) -> 192.14042 | L2: =AVERAGE($H$2:$H$101) -> 195.0762 | M2: =AVERAGE($I$2:$I$101) -> 5.088 | N2: =2.114*$M2 -> 10.756032 | O2: =0*$M2 -> 0 | P2: =IF(H2>J2,"⚠️ FUERA — Encima LCS",IF(H2<K2,"⚠️ FUERA — Bajo LCI","✅ DENTRO")) -> ✅ DENTRO | Q2: =IF(I2>N2,"⚠️ FUERA — Encima LCS","✅ DENTRO") -> ✅ DENTRO
A3: ="SUB-"&TEXT(INT((ROW()-2)/5)+1,"000") -> SUB-001 | B3: =INDEX(Lotes!$A$2:$A$21,INT((ROW()-2)/5)+1) -> RETEX-2024-001 | C3: =INDEX(Lotes!$B$2:$B$21,INT((ROW()-2)/5)+1) -> 46095 | D3: =INDEX(Lotes!$C$2:$C$21,INT((ROW()-2)/5)+1) -> 11 | E3: =INDEX(Lotes!$F$2:$F$21,INT((ROW()-2)/5)+1) -> Matutino | F3: =MOD(ROW()-2,5)+1 -> 2 | G3: 193.44 | H3: =AVERAGE(INDEX($G$2:$G$101,INT((ROW()-2)/5)*5+1):INDEX($G$2:$G$101,INT((ROW()-2)/5)*5+5)) -> 194.086 | I3: =MAX(INDEX($G$2:$G$101,INT((ROW()-2)/5)*5+1):INDEX($G$2:$G$101,INT((ROW()-2)/5)*5+5))-MIN(INDEX($G$2:$G$101,INT((ROW()-2)/5)*5+1):INDEX($G$2:$G$101,INT((ROW()-2)/5)*5+5)) -> 4.13 | J3: =$L3+(0.577*$M3) -> 198.01198 | K3: =$L3-(0.577*$M3) -> 192.14042 | L3: =AVERAGE($H$2:$H$101) -> 195.0762 | M3: =AVERAGE($I$2:$I$101) -> 5.088 | N3: =2.114*$M3 -> 10.756032 | O3: =0*$M3 -> 0 | P3: =IF(H3>J3,"⚠️ FUERA — Encima LCS",IF(H3<K3,"⚠️ FUERA — Bajo LCI","✅ DENTRO")) -> ✅ DENTRO | Q3: =IF(I3>N3,"⚠️ FUERA — Encima LCS","✅ DENTRO") -> ✅ DENTRO
A4: ="SUB-"&TEXT(INT((ROW()-2)/5)+1,"000") -> SUB-001 | B4: =INDEX(Lotes!$A$2:$A$21,INT((ROW()-2)/5)+1) -> RETEX-2024-001 | C4: =INDEX(Lotes!$B$2:$B$21,INT((ROW()-2)/5)+1) -> 46095 | D4: =INDEX(Lotes!$C$2:$C$21,INT((ROW()-2)/5)+1) -> 11 | E4: =INDEX(Lotes!$F$2:$F$21,INT((ROW()-2)/5)+1) -> Matutino | F4: =MOD(ROW()-2,5)+1 -> 3 | G4: 191.82 | H4: =AVERAGE(INDEX($G$2:$G$101,INT((ROW()-2)/5)*5+1):INDEX($G$2:$G$101,INT((ROW()-2)/5)*5+5)) -> 194.086 | I4: =MAX(INDEX($G$2:$G$101,INT((ROW()-2)/5)*5+1):INDEX($G$2:$G$101,INT((ROW()-2)/5)*5+5))-MIN(INDEX($G$2:$G$101,INT((ROW()-2)/5)*5+1):INDEX($G$2:$G$101,INT((ROW()-2)/5)*5+5)) -> 4.13 | J4: =$L4+(0.577*$M4) -> 198.01198 | K4: =$L4-(0.577*$M4) -> 192.14042 | L4: =AVERAGE($H$2:$H$101) -> 195.0762 | M4: =AVERAGE($I$2:$I$101) -> 5.088 | N4: =2.114*$M4 -> 10.756032 | O4: =0*$M4 -> 0 | P4: =IF(H4>J4,"⚠️ FUERA — Encima LCS",IF(H4<K4,"⚠️ FUERA — Bajo LCI","✅ DENTRO")) -> ✅ DENTRO | Q4: =IF(I4>N4,"⚠️ FUERA — Encima LCS","✅ DENTRO") -> ✅ DENTRO
A5: ="SUB-"&TEXT(INT((ROW()-2)/5)+1,"000") -> SUB-001 | B5: =INDEX(Lotes!$A$2:$A$21,INT((ROW()-2)/5)+1) -> RETEX-2024-001 | C5: =INDEX(Lotes!$B$2:$B$21,INT((ROW()-2)/5)+1) -> 46095 | D5: =INDEX(Lotes!$C$2:$C$21,INT((ROW()-2)/5)+1) -> 11 | E5: =INDEX(Lotes!$F$2:$F$21,INT((ROW()-2)/5)+1) -> Matutino | F5: =MOD(ROW()-2,5)+1 -> 4 | G5: 195.95 | H5: =AVERAGE(INDEX($G$2:$G$101,INT((ROW()-2)/5)*5+1):INDEX($G$2:$G$101,INT((ROW()-2)/5)*5+5)) -> 194.086 | I5: =MAX(INDEX($G$2:$G$101,INT((ROW()-2)/5)*5+1):INDEX($G$2:$G$101,INT((ROW()-2)/5)*5+5))-MIN(INDEX($G$2:$G$101,INT((ROW()-2)/5)*5+1):INDEX($G$2:$G$101,INT((ROW()-2)/5)*5+5)) -> 4.13 | J5: =$L5+(0.577*$M5) -> 198.01198 | K5: =$L5-(0.577*$M5) -> 192.14042 | L5: =AVERAGE($H$2:$H$101) -> 195.0762 | M5: =AVERAGE($I$2:$I$101) -> 5.088 | N5: =2.114*$M5 -> 10.756032 | O5: =0*$M5 -> 0 | P5: =IF(H5>J5,"⚠️ FUERA — Encima LCS",IF(H5<K5,"⚠️ FUERA — Bajo LCI","✅ DENTRO")) -> ✅ DENTRO | Q5: =IF(I5>N5,"⚠️ FUERA — Encima LCS","✅ DENTRO") -> ✅ DENTRO
A6: ="SUB-"&TEXT(INT((ROW()-2)/5)+1,"000") -> SUB-001 | B6: =INDEX(Lotes!$A$2:$A$21,INT((ROW()-2)/5)+1) -> RETEX-2024-001 | C6: =INDEX(Lotes!$B$2:$B$21,INT((ROW()-2)/5)+1) -> 46095 | D6: =INDEX(Lotes!$C$2:$C$21,INT((ROW()-2)/5)+1) -> 11 | E6: =INDEX(Lotes!$F$2:$F$21,INT((ROW()-2)/5)+1) -> Matutino | F6: =MOD(ROW()-2,5)+1 -> 5 | G6: 194.32 | H6: =AVERAGE(INDEX($G$2:$G$101,INT((ROW()-2)/5)*5+1):INDEX($G$2:$G$101,INT((ROW()-2)/5)*5+5)) -> 194.086 | I6: =MAX(INDEX($G$2:$G$101,INT((ROW()-2)/5)*5+1):INDEX($G$2:$G$101,INT((ROW()-2)/5)*5+5))-MIN(INDEX($G$2:$G$101,INT((ROW()-2)/5)*5+1):INDEX($G$2:$G$101,INT((ROW()-2)/5)*5+5)) -> 4.13 | J6: =$L6+(0.577*$M6) -> 198.01198 | K6: =$L6-(0.577*$M6) -> 192.14042 | L6: =AVERAGE($H$2:$H$101) -> 195.0762 | M6: =AVERAGE($I$2:$I$101) -> 5.088 | N6: =2.114*$M6 -> 10.756032 | O6: =0*$M6 -> 0 | P6: =IF(H6>J6,"⚠️ FUERA — Encima LCS",IF(H6<K6,"⚠️ FUERA — Bajo LCI","✅ DENTRO")) -> ✅ DENTRO | Q6: =IF(I6>N6,"⚠️ FUERA — Encima LCS","✅ DENTRO") -> ✅ DENTRO
A7: ="SUB-"&TEXT(INT((ROW()-2)/5)+1,"000") -> SUB-002 | B7: =INDEX(Lotes!$A$2:$A$21,INT((ROW()-2)/5)+1) -> RETEX-2024-002 | C7: =INDEX(Lotes!$B$2:$B$21,INT((ROW()-2)/5)+1) -> 46102 | D7: =INDEX(Lotes!$C$2:$C$21,INT((ROW()-2)/5)+1) -> 12 | E7: =INDEX(Lotes!$F$2:$F$21,INT((ROW()-2)/5)+1) -> Vespertino | F7: =MOD(ROW()-2,5)+1 -> 1 | G7: 193.81 | H7: =AVERAGE(INDEX($G$2:$G$101,INT((ROW()-2)/5)*5+1):INDEX($G$2:$G$101,INT((ROW()-2)/5)*5+5)) -> 195.45 | I7: =MAX(INDEX($G$2:$G$101,INT((ROW()-2)/5)*5+1):INDEX($G$2:$G$101,INT((ROW()-2)/5)*5+5))-MIN(INDEX($G$2:$G$101,INT((ROW()-2)/5)*5+1):INDEX($G$2:$G$101,INT((ROW()-2)/5)*5+5)) -> 5.02 | J7: =$L7+(0.577*$M7) -> 198.01198 | K7: =$L7-(0.577*$M7) -> 192.14042 | L7: =AVERAGE($H$2:$H$101) -> 195.0762 | M7: =AVERAGE($I$2:$I$101) -> 5.088 | N7: =2.114*$M7 -> 10.756032 | O7: =0*$M7 -> 0 | P7: =IF(H7>J7,"⚠️ FUERA — Encima LCS",IF(H7<K7,"⚠️ FUERA — Bajo LCI","✅ DENTRO")) -> ✅ DENTRO | Q7: =IF(I7>N7,"⚠️ FUERA — Encima LCS","✅ DENTRO") -> ✅ DENTRO
A8: ="SUB-"&TEXT(INT((ROW()-2)/5)+1,"000") -> SUB-002 | B8: =INDEX(Lotes!$A$2:$A$21,INT((ROW()-2)/5)+1) -> RETEX-2024-002 | C8: =INDEX(Lotes!$B$2:$B$21,INT((ROW()-2)/5)+1) -> 46102 | D8: =INDEX(Lotes!$C$2:$C$21,INT((ROW()-2)/5)+1) -> 12 | E8: =INDEX(Lotes!$F$2:$F$21,INT((ROW()-2)/5)+1) -> Vespertino | F8: =MOD(ROW()-2,5)+1 -> 2 | G8: 198.83 | H8: =AVERAGE(INDEX($G$2:$G$101,INT((ROW()-2)/5)*5+1):INDEX($G$2:$G$101,INT((ROW()-2)/5)*5+5)) -> 195.45 | I8: =MAX(INDEX($G$2:$G$101,INT((ROW()-2)/5)*5+1):INDEX($G$2:$G$101,INT((ROW()-2)/5)*5+5))-MIN(INDEX($G$2:$G$101,INT((ROW()-2)/5)*5+1):INDEX($G$2:$G$101,INT((ROW()-2)/5)*5+5)) -> 5.02 | J8: =$L8+(0.577*$M8) -> 198.01198 | K8: =$L8-(0.577*$M8) -> 192.14042 | L8: =AVERAGE($H$2:$H$101) -> 195.0762 | M8: =AVERAGE($I$2:$I$101) -> 5.088 | N8: =2.114*$M8 -> 10.756032 | O8: =0*$M8 -> 0 | P8: =IF(H8>J8,"⚠️ FUERA — Encima LCS",IF(H8<K8,"⚠️ FUERA — Bajo LCI","✅ DENTRO")) -> ✅ DENTRO | Q8: =IF(I8>N8,"⚠️ FUERA — Encima LCS","✅ DENTRO") -> ✅ DENTRO
A9: ="SUB-"&TEXT(INT((ROW()-2)/5)+1,"000") -> SUB-002 | B9: =INDEX(Lotes!$A$2:$A$21,INT((ROW()-2)/5)+1) -> RETEX-2024-002 | C9: =INDEX(Lotes!$B$2:$B$21,INT((ROW()-2)/5)+1) -> 46102 | D9: =INDEX(Lotes!$C$2:$C$21,INT((ROW()-2)/5)+1) -> 12 | E9: =INDEX(Lotes!$F$2:$F$21,INT((ROW()-2)/5)+1) -> Vespertino | F9: =MOD(ROW()-2,5)+1 -> 3 | G9: 194.82 | H9: =AVERAGE(INDEX($G$2:$G$101,INT((ROW()-2)/5)*5+1):INDEX($G$2:$G$101,INT((ROW()-2)/5)*5+5)) -> 195.45 | I9: =MAX(INDEX($G$2:$G$101,INT((ROW()-2)/5)*5+1):INDEX($G$2:$G$101,INT((ROW()-2)/5)*5+5))-MIN(INDEX($G$2:$G$101,INT((ROW()-2)/5)*5+1):INDEX($G$2:$G$101,INT((ROW()-2)/5)*5+5)) -> 5.02 | J9: =$L9+(0.577*$M9) -> 198.01198 | K9: =$L9-(0.577*$M9) -> 192.14042 | L9: =AVERAGE($H$2:$H$101) -> 195.0762 | M9: =AVERAGE($I$2:$I$101) -> 5.088 | N9: =2.114*$M9 -> 10.756032 | O9: =0*$M9 -> 0 | P9: =IF(H9>J9,"⚠️ FUERA — Encima LCS",IF(H9<K9,"⚠️ FUERA — Bajo LCI","✅ DENTRO")) -> ✅ DENTRO | Q9: =IF(I9>N9,"⚠️ FUERA — Encima LCS","✅ DENTRO") -> ✅ DENTRO
A10: ="SUB-"&TEXT(INT((ROW()-2)/5)+1,"000") -> SUB-002 | B10: =INDEX(Lotes!$A$2:$A$21,INT((ROW()-2)/5)+1) -> RETEX-2024-002 | C10: =INDEX(Lotes!$B$2:$B$21,INT((ROW()-2)/5)+1) -> 46102 | D10: =INDEX(Lotes!$C$2:$C$21,INT((ROW()-2)/5)+1) -> 12 | E10: =INDEX(Lotes!$F$2:$F$21,INT((ROW()-2)/5)+1) -> Vespertino | F10: =MOD(ROW()-2,5)+1 -> 4 | G10: 195.47 | H10: =AVERAGE(INDEX($G$2:$G$101,INT((ROW()-2)/5)*5+1):INDEX($G$2:$G$101,INT((ROW()-2)/5)*5+5)) -> 195.45 | I10: =MAX(INDEX($G$2:$G$101,INT((ROW()-2)/5)*5+1):INDEX($G$2:$G$101,INT((ROW()-2)/5)*5+5))-MIN(INDEX($G$2:$G$101,INT((ROW()-2)/5)*5+1):INDEX($G$2:$G$101,INT((ROW()-2)/5)*5+5)) -> 5.02 | J10: =$L10+(0.577*$M10) -> 198.01198 | K10: =$L10-(0.577*$M10) -> 192.14042 | L10: =AVERAGE($H$2:$H$101) -> 195.0762 | M10: =AVERAGE($I$2:$I$101) -> 5.088 | N10: =2.114*$M10 -> 10.756032 | O10: =0*$M10 -> 0 | P10: =IF(H10>J10,"⚠️ FUERA — Encima LCS",IF(H10<K10,"⚠️ FUERA — Bajo LCI","✅ DENTRO")) -> ✅ DENTRO | Q10: =IF(I10>N10,"⚠️ FUERA — Encima LCS","✅ DENTRO") -> ✅ DENTRO
A11: ="SUB-"&TEXT(INT((ROW()-2)/5)+1,"000") -> SUB-002 | B11: =INDEX(Lotes!$A$2:$A$21,INT((ROW()-2)/5)+1) -> RETEX-2024-002 | C11: =INDEX(Lotes!$B$2:$B$21,INT((ROW()-2)/5)+1) -> 46102 | D11: =INDEX(Lotes!$C$2:$C$21,INT((ROW()-2)/5)+1) -> 12 | E11: =INDEX(Lotes!$F$2:$F$21,INT((ROW()-2)/5)+1) -> Vespertino | F11: =MOD(ROW()-2,5)+1 -> 5 | G11: 194.32 | H11: =AVERAGE(INDEX($G$2:$G$101,INT((ROW()-2)/5)*5+1):INDEX($G$2:$G$101,INT((ROW()-2)/5)*5+5)) -> 195.45 | I11: =MAX(INDEX($G$2:$G$101,INT((ROW()-2)/5)*5+1):INDEX($G$2:$G$101,INT((ROW()-2)/5)*5+5))-MIN(INDEX($G$2:$G$101,INT((ROW()-2)/5)*5+1):INDEX($G$2:$G$101,INT((ROW()-2)/5)*5+5)) -> 5.02 | J11: =$L11+(0.577*$M11) -> 198.01198 | K11: =$L11-(0.577*$M11) -> 192.14042 | L11: =AVERAGE($H$2:$H$101) -> 195.0762 | M11: =AVERAGE($I$2:$I$101) -> 5.088 | N11: =2.114*$M11 -> 10.756032 | O11: =0*$M11 -> 0 | P11: =IF(H11>J11,"⚠️ FUERA — Encima LCS",IF(H11<K11,"⚠️ FUERA — Bajo LCI","✅ DENTRO")) -> ✅ DENTRO | Q11: =IF(I11>N11,"⚠️ FUERA — Encima LCS","✅ DENTRO") -> ✅ DENTRO
A12: ="SUB-"&TEXT(INT((ROW()-2)/5)+1,"000") -> SUB-003 | B12: =INDEX(Lotes!$A$2:$A$21,INT((ROW()-2)/5)+1) -> RETEX-2024-003 | C12: =INDEX(Lotes!$B$2:$B$21,INT((ROW()-2)/5)+1) -> 46109 | D12: =INDEX(Lotes!$C$2:$C$21,INT((ROW()-2)/5)+1) -> 13 | E12: =INDEX(Lotes!$F$2:$F$21,INT((ROW()-2)/5)+1) -> Nocturno | F12: =MOD(ROW()-2,5)+1 -> 1 | G12: 196.98 | H12: =AVERAGE(INDEX($G$2:$G$101,INT((ROW()-2)/5)*5+1):INDEX($G$2:$G$101,INT((ROW()-2)/5)*5+5)) -> 195.964 | I12: =MAX(INDEX($G$2:$G$101,INT((ROW()-2)/5)*5+1):INDEX($G$2:$G$101,INT((ROW()-2)/5)*5+5))-MIN(INDEX($G$2:$G$101,INT((ROW()-2)/5)*5+1):INDEX($G$2:$G$101,INT((ROW()-2)/5)*5+5)) -> 3.55 | J12: =$L12+(0.577*$M12) -> 198.01198 | K12: =$L12-(0.577*$M12) -> 192.14042 | L12: =AVERAGE($H$2:$H$101) -> 195.0762 | M12: =AVERAGE($I$2:$I$101) -> 5.088 | N12: =2.114*$M12 -> 10.756032 | O12: =0*$M12 -> 0 | P12: =IF(H12>J12,"⚠️ FUERA — Encima LCS",IF(H12<K12,"⚠️ FUERA — Bajo LCI","✅ DENTRO")) -> ✅ DENTRO | Q12: =IF(I12>N12,"⚠️ FUERA — Encima LCS","✅ DENTRO") -> ✅ DENTRO
A13: ="SUB-"&TEXT(INT((ROW()-2)/5)+1,"000") -> SUB-003 | B13: =INDEX(Lotes!$A$2:$A$21,INT((ROW()-2)/5)+1) -> RETEX-2024-003 | C13: =INDEX(Lotes!$B$2:$B$21,INT((ROW()-2)/5)+1) -> 46109 | D13: =INDEX(Lotes!$C$2:$C$21,INT((ROW()-2)/5)+1) -> 13 | E13: =INDEX(Lotes!$F$2:$F$21,INT((ROW()-2)/5)+1) -> Nocturno | F13: =MOD(ROW()-2,5)+1 -> 2 | G13: 195.07 | H13: =AVERAGE(INDEX($G$2:$G$101,INT((ROW()-2)/5)*5+1):INDEX($G$2:$G$101,INT((ROW()-2)/5)*5+5)) -> 195.964 | I13: =MAX(INDEX($G$2:$G$101,INT((ROW()-2)/5)*5+1):INDEX($G$2:$G$101,INT((ROW()-2)/5)*5+5))-MIN(INDEX($G$2:$G$101,INT((ROW()-2)/5)*5+1):INDEX($G$2:$G$101,INT((ROW()-2)/5)*5+5)) -> 3.55 | J13: =$L13+(0.577*$M13) -> 198.01198 | K13: =$L13-(0.577*$M13) -> 192.14042 | L13: =AVERAGE($H$2:$H$101) -> 195.0762 | M13: =AVERAGE($I$2:$I$101) -> 5.088 | N13: =2.114*$M13 -> 10.756032 | O13: =0*$M13 -> 0 | P13: =IF(H13>J13,"⚠️ FUERA — Encima LCS",IF(H13<K13,"⚠️ FUERA — Bajo LCI","✅ DENTRO")) -> ✅ DENTRO | Q13: =IF(I13>N13,"⚠️ FUERA — Encima LCS","✅ DENTRO") -> ✅ DENTRO
A14: ="SUB-"&TEXT(INT((ROW()-2)/5)+1,"000") -> SUB-003 | B14: =INDEX(Lotes!$A$2:$A$21,INT((ROW()-2)/5)+1) -> RETEX-2024-003 | C14: =INDEX(Lotes!$B$2:$B$21,INT((ROW()-2)/5)+1) -> 46109 | D14: =INDEX(Lotes!$C$2:$C$21,INT((ROW()-2)/5)+1) -> 13 | E14: =INDEX(Lotes!$F$2:$F$21,INT((ROW()-2)/5)+1) -> Nocturno | F14: =MOD(ROW()-2,5)+1 -> 3 | G14: 194.98 | H14: =AVERAGE(INDEX($G$2:$G$101,INT((ROW()-2)/5)*5+1):INDEX($G$2:$G$101,INT((ROW()-2)/5)*5+5)) -> 195.964 | I14: =MAX(INDEX($G$2:$G$101,INT((ROW()-2)/5)*5+1):INDEX($G$2:$G$101,INT((ROW()-2)/5)*5+5))-MIN(INDEX($G$2:$G$101,INT((ROW()-2)/5)*5+1):INDEX($G$2:$G$101,INT((ROW()-2)/5)*5+5)) -> 3.55 | J14: =$L14+(0.577*$M14) -> 198.01198 | K14: =$L14-(0.577*$M14) -> 192.14042 | L14: =AVERAGE($H$2:$H$101) -> 195.0762 | M14: =AVERAGE($I$2:$I$101) -> 5.088 | N14: =2.114*$M14 -> 10.756032 | O14: =0*$M14 -> 0 | P14: =IF(H14>J14,"⚠️ FUERA — Encima LCS",IF(H14<K14,"⚠️ FUERA — Bajo LCI","✅ DENTRO")) -> ✅ DENTRO | Q14: =IF(I14>N14,"⚠️ FUERA — Encima LCS","✅ DENTRO") -> ✅ DENTRO
... A101: ="SUB-"&TEXT(INT((ROW()-2)/5)+1,"000") -> SUB-020 | B101: =INDEX(Lotes!$A$2:$A$21,INT((ROW()-2)/5)+1) -> RETEX-2024-020 | C101: =INDEX(Lotes!$B$2:$B$21,INT((ROW()-2)/5)+1) -> 46228 | D101: =INDEX(Lotes!$C$2:$C$21,INT((ROW()-2)/5)+1) -> 30 | E101: =INDEX(Lotes!$F$2:$F$21,INT((ROW()-2)/5)+1) -> Vespertino | F101: =MOD(ROW()-2,5)+1 -> 5 | G101: 194.46 | H101: =AVERAGE(INDEX($G$2:$G$101,INT((ROW()-2)/5)*5+1):INDEX($G$2:$G$101,INT((ROW()-2)/5)*5+5)) -> 195.228 | I101: =MAX(INDEX($G$2:$G$101,INT((ROW()-2)/5)*5+1):INDEX($G$2:$G$101,INT((ROW()-2)/5)*5+5))-MIN(INDEX($G$2:$G$101,INT((ROW()-2)/5)*5+1):INDEX($G$2:$G$101,INT((ROW()-2)/5)*5+5)) -> 6.01 | J101: =$L101+(0.577*$M101) -> 198.01198 | K101: =$L101-(0.577*$M101) -> 192.14042 | L101: =AVERAGE($H$2:$H$101) -> 195.0762 | M101: =AVERAGE($I$2:$I$101) -> 5.088 | N101: =2.114*$M101 -> 10.756032 | O101: =0*$M101 -> 0 | P101: =IF(H101>J101,"⚠️ FUERA — Encima LCS",IF(H101<K101,"⚠️ FUERA — Bajo LCI","✅ DENTRO")) -> ✅ DENTRO | Q101: =IF(I101>N101,"⚠️ FUERA — Encima LCS","✅ DENTRO") -> ✅ DENTRO

Sheet KPIs_Diarios
A1: ID_KPI | B1: Fecha | C1: Semana | D1: ID_Lote | E1: Mes | F1: Tipo_KPI | G1: Valor_Medido | H1: Umbral_Alerta | I1: Unidad | J1: Resultado | K1: Semaforo | L1: Responsable
A2: ="KPI-"&TEXT(ROW()-1,"000") -> KPI-001 | B2: =INDEX(Lotes!$B$2:$B$53,INT((ROW()-2)/6)+1) -> 46095 | C2: =INDEX(Lotes!$C$2:$C$53,INT((ROW()-2)/6)+1) -> 11 | D2: =INDEX(Lotes!$A$2:$A$53,INT((ROW()-2)/6)+1) -> RETEX-2024-001 | E2: =INDEX(Lotes!$D$2:$D$53,INT((ROW()-2)/6)+1) -> marzo | F2: IPL | G2: 97.75 | H2: =IF(F2="IPL",96,IF(F2="RS",70,IF(F2="VH",8,IF(F2="TR",1,IF(F2="TEC",3,1))))) -> 96 | I2: =IF(F2="IPL","%pureza",IF(F2="RS","%rendimiento",IF(F2="VH","%humedad",IF(F2="TR","%retorno",IF(F2="TEC","%error","índice"))))) -> %pureza | J2: =IF(OR(F2="IPL",F2="RS",F2="Cpk_Mensual"),IF(G2<H2,"❌ ALERTA","✅ OK"),IF(G2>H2,"❌ ALERTA","✅ OK")) -> ✅ OK | K2: =IF(OR(F2="IPL",F2="RS",F2="Cpk_Mensual"),IF(G2<H2,"🔴 ALERTA",IF(G2<H2*1.05,"🟡 PRECAUCIÓN","🟢 OK")),IF(G2>H2,"🔴 ALERTA",IF(G2>H2*0.85,"🟡 PRECAUCIÓN","🟢 OK"))) -> 🟡 PRECAUCIÓN | L2: =IF(F2="IPL","Inspector de Calidad",IF(F2="RS","Coordinador de Planta",IF(F2="VH","Almacenista",IF(F2="TR","Gerente de Calidad",IF(F2="TEC","Supervisor","Ingeniero de Calidad"))))) -> Inspector de Calidad
A3: ="KPI-"&TEXT(ROW()-1,"000") -> KPI-002 | B3: =INDEX(Lotes!$B$2:$B$53,INT((ROW()-2)/6)+1) -> 46095 | C3: =INDEX(Lotes!$C$2:$C$53,INT((ROW()-2)/6)+1) -> 11 | D3: =INDEX(Lotes!$A$2:$A$53,INT((ROW()-2)/6)+1) -> RETEX-2024-001 | E3: =INDEX(Lotes!$D$2:$D$53,INT((ROW()-2)/6)+1) -> marzo | F3: RS | G3: 72.93 | H3: =IF(F3="IPL",96,IF(F3="RS",70,IF(F3="VH",8,IF(F3="TR",1,IF(F3="TEC",3,1))))) -> 70 | I3: =IF(F3="IPL","%pureza",IF(F3="RS","%rendimiento",IF(F3="VH","%humedad",IF(F3="TR","%retorno",IF(F3="TEC","%error","índice"))))) -> %rendimiento | J3: =IF(OR(F3="IPL",F3="RS",F3="Cpk_Mensual"),IF(G3<H3,"❌ ALERTA","✅ OK"),IF(G3>H3,"❌ ALERTA","✅ OK")) -> ✅ OK | K3: =IF(OR(F3="IPL",F3="RS",F3="Cpk_Mensual"),IF(G3<H3,"🔴 ALERTA",IF(G3<H3*1.05,"🟡 PRECAUCIÓN","🟢 OK")),IF(G3>H3,"🔴 ALERTA",IF(G3>H3*0.85,"🟡 PRECAUCIÓN","🟢 OK"))) -> 🟡 PRECAUCIÓN | L3: =IF(F3="IPL","Inspector de Calidad",IF(F3="RS","Coordinador de Planta",IF(F3="VH","Almacenista",IF(F3="TR","Gerente de Calidad",IF(F3="TEC","Supervisor","Ingeniero de Calidad"))))) -> Coordinador de Planta
A4: ="KPI-"&TEXT(ROW()-1,"000") -> KPI-003 | B4: =INDEX(Lotes!$B$2:$B$53,INT((ROW()-2)/6)+1) -> 46095 | C4: =INDEX(Lotes!$C$2:$C$53,INT((ROW()-2)/6)+1) -> 11 | D4: =INDEX(Lotes!$A$2:$A$53,INT((ROW()-2)/6)+1) -> RETEX-2024-001 | E4: =INDEX(Lotes!$D$2:$D$53,INT((ROW()-2)/6)+1) -> marzo | F4: VH | G4: 7.38 | H4: =IF(F4="IPL",96,IF(F4="RS",70,IF(F4="VH",8,IF(F4="TR",1,IF(F4="TEC",3,1))))) -> 8 | I4: =IF(F4="IPL","%pureza",IF(F4="RS","%rendimiento",IF(F4="VH","%humedad",IF(F4="TR","%retorno",IF(F4="TEC","%error","índice"))))) -> %humedad | J4: =IF(OR(F4="IPL",F4="RS",F4="Cpk_Mensual"),IF(G4<H4,"❌ ALERTA","✅ OK"),IF(G4>H4,"❌ ALERTA","✅ OK")) -> ✅ OK | K4: =IF(OR(F4="IPL",F4="RS",F4="Cpk_Mensual"),IF(G4<H4,"🔴 ALERTA",IF(G4<H4*1.05,"🟡 PRECAUCIÓN","🟢 OK")),IF(G4>H4,"🔴 ALERTA",IF(G4>H4*0.85,"🟡 PRECAUCIÓN","🟢 OK"))) -> 🟡 PRECAUCIÓN | L4: =IF(F4="IPL","Inspector de Calidad",IF(F4="RS","Coordinador de Planta",IF(F4="VH","Almacenista",IF(F4="TR","Gerente de Calidad",IF(F4="TEC","Supervisor","Ingeniero de Calidad"))))) -> Almacenista
A5: ="KPI-"&TEXT(ROW()-1,"000") -> KPI-004 | B5: =INDEX(Lotes!$B$2:$B$53,INT((ROW()-2)/6)+1) -> 46095 | C5: =INDEX(Lotes!$C$2:$C$53,INT((ROW()-2)/6)+1) -> 11 | D5: =INDEX(Lotes!$A$2:$A$53,INT((ROW()-2)/6)+1) -> RETEX-2024-001 | E5: =INDEX(Lotes!$D$2:$D$53,INT((ROW()-2)/6)+1) -> marzo | F5: TR | G5: 0.78 | H5: =IF(F5="IPL",96,IF(F5="RS",70,IF(F5="VH",8,IF(F5="TR",1,IF(F5="TEC",3,1))))) -> 1 | I5: =IF(F5="IPL","%pureza",IF(F5="RS","%rendimiento",IF(F5="VH","%humedad",IF(F5="TR","%retorno",IF(F5="TEC","%error","índice"))))) -> %retorno | J5: =IF(OR(F5="IPL",F5="RS",F5="Cpk_Mensual"),IF(G5<H5,"❌ ALERTA","✅ OK"),IF(G5>H5,"❌ ALERTA","✅ OK")) -> ✅ OK | K5: =IF(OR(F5="IPL",F5="RS",F5="Cpk_Mensual"),IF(G5<H5,"🔴 ALERTA",IF(G5<H5*1.05,"🟡 PRECAUCIÓN","🟢 OK")),IF(G5>H5,"🔴 ALERTA",IF(G5>H5*0.85,"🟡 PRECAUCIÓN","🟢 OK"))) -> 🟢 OK | L5: =IF(F5="IPL","Inspector de Calidad",IF(F5="RS","Coordinador de Planta",IF(F5="VH","Almacenista",IF(F5="TR","Gerente de Calidad",IF(F5="TEC","Supervisor","Ingeniero de Calidad"))))) -> Gerente de Calidad
A6: ="KPI-"&TEXT(ROW()-1,"000") -> KPI-005 | B6: =INDEX(Lotes!$B$2:$B$53,INT((ROW()-2)/6)+1) -> 46095 | C6: =INDEX(Lotes!$C$2:$C$53,INT((ROW()-2)/6)+1) -> 11 | D6: =INDEX(Lotes!$A$2:$A$53,INT((ROW()-2)/6)+1) -> RETEX-2024-001 | E6: =INDEX(Lotes!$D$2:$D$53,INT((ROW()-2)/6)+1) -> marzo | F6: TEC | G6: 1.88 | H6: =IF(F6="IPL",96,IF(F6="RS",70,IF(F6="VH",8,IF(F6="TR",1,IF(F6="TEC",3,1))))) -> 3 | I6: =IF(F6="IPL","%pureza",IF(F6="RS","%rendimiento",IF(F6="VH","%humedad",IF(F6="TR","%retorno",IF(F6="TEC","%error","índice"))))) -> %error | J6: =IF(OR(F6="IPL",F6="RS",F6="Cpk_Mensual"),IF(G6<H6,"❌ ALERTA","✅ OK"),IF(G6>H6,"❌ ALERTA","✅ OK")) -> ✅ OK | K6: =IF(OR(F6="IPL",F6="RS",F6="Cpk_Mensual"),IF(G6<H6,"🔴 ALERTA",IF(G6<H6*1.05,"🟡 PRECAUCIÓN","🟢 OK")),IF(G6>H6,"🔴 ALERTA",IF(G6>H6*0.85,"🟡 PRECAUCIÓN","🟢 OK"))) -> 🟢 OK | L6: =IF(F6="IPL","Inspector de Calidad",IF(F6="RS","Coordinador de Planta",IF(F6="VH","Almacenista",IF(F6="TR","Gerente de Calidad",IF(F6="TEC","Supervisor","Ingeniero de Calidad"))))) -> Supervisor
A7: ="KPI-"&TEXT(ROW()-1,"000") -> KPI-006 | B7: =INDEX(Lotes!$B$2:$B$53,INT((ROW()-2)/6)+1) -> 46095 | C7: =INDEX(Lotes!$C$2:$C$53,INT((ROW()-2)/6)+1) -> 11 | D7: =INDEX(Lotes!$A$2:$A$53,INT((ROW()-2)/6)+1) -> RETEX-2024-001 | E7: =INDEX(Lotes!$D$2:$D$53,INT((ROW()-2)/6)+1) -> marzo | F7: CPK_MENSUAL | G7: 0.84 | H7: =IF(F7="IPL",96,IF(F7="RS",70,IF(F7="VH",8,IF(F7="TR",1,IF(F7="TEC",3,1))))) -> 1 | I7: =IF(F7="IPL","%pureza",IF(F7="RS","%rendimiento",IF(F7="VH","%humedad",IF(F7="TR","%retorno",IF(F7="TEC","%error","índice"))))) -> índice | J7: =IF(OR(F7="IPL",F7="RS",F7="Cpk_Mensual"),IF(G7<H7,"❌ ALERTA","✅ OK"),IF(G7>H7,"❌ ALERTA","✅ OK")) -> ❌ ALERTA | K7: =IF(OR(F7="IPL",F7="RS",F7="Cpk_Mensual"),IF(G7<H7,"🔴 ALERTA",IF(G7<H7*1.05,"🟡 PRECAUCIÓN","🟢 OK")),IF(G7>H7,"🔴 ALERTA",IF(G7>H7*0.85,"🟡 PRECAUCIÓN","🟢 OK"))) -> 🔴 ALERTA | L7: =IF(F7="IPL","Inspector de Calidad",IF(F7="RS","Coordinador de Planta",IF(F7="VH","Almacenista",IF(F7="TR","Gerente de Calidad",IF(F7="TEC","Supervisor","Ingeniero de Calidad"))))) -> Ingeniero de Calidad
A8: ="KPI-"&TEXT(ROW()-1,"000") -> KPI-007 | B8: =INDEX(Lotes!$B$2:$B$53,INT((ROW()-2)/6)+1) -> 46102 | C8: =INDEX(Lotes!$C$2:$C$53,INT((ROW()-2)/6)+1) -> 12 | D8: =INDEX(Lotes!$A$2:$A$53,INT((ROW()-2)/6)+1) -> RETEX-2024-002 | E8: =INDEX(Lotes!$D$2:$D$53,INT((ROW()-2)/6)+1) -> marzo | F8: IPL | G8: 97.66 | H8: =IF(F8="IPL",96,IF(F8="RS",70,IF(F8="VH",8,IF(F8="TR",1,IF(F8="TEC",3,1))))) -> 96 | I8: =IF(F8="IPL","%pureza",IF(F8="RS","%rendimiento",IF(F8="VH","%humedad",IF(F8="TR","%retorno",IF(F8="TEC","%error","índice"))))) -> %pureza | J8: =IF(OR(F8="IPL",F8="RS",F8="Cpk_Mensual"),IF(G8<H8,"❌ ALERTA","✅ OK"),IF(G8>H8,"❌ ALERTA","✅ OK")) -> ✅ OK | K8: =IF(OR(F8="IPL",F8="RS",F8="Cpk_Mensual"),IF(G8<H8,"🔴 ALERTA",IF(G8<H8*1.05,"🟡 PRECAUCIÓN","🟢 OK")),IF(G8>H8,"🔴 ALERTA",IF(G8>H8*0.85,"🟡 PRECAUCIÓN","🟢 OK"))) -> 🟡 PRECAUCIÓN | L8: =IF(F8="IPL","Inspector de Calidad",IF(F8="RS","Coordinador de Planta",IF(F8="VH","Almacenista",IF(F8="TR","Gerente de Calidad",IF(F8="TEC","Supervisor","Ingeniero de Calidad"))))) -> Inspector de Calidad
A9: ="KPI-"&TEXT(ROW()-1,"000") -> KPI-008 | B9: =INDEX(Lotes!$B$2:$B$53,INT((ROW()-2)/6)+1) -> 46102 | C9: =INDEX(Lotes!$C$2:$C$53,INT((ROW()-2)/6)+1) -> 12 | D9: =INDEX(Lotes!$A$2:$A$53,INT((ROW()-2)/6)+1) -> RETEX-2024-002 | E9: =INDEX(Lotes!$D$2:$D$53,INT((ROW()-2)/6)+1) -> marzo | F9: RS | G9: 71.33 | H9: =IF(F9="IPL",96,IF(F9="RS",70,IF(F9="VH",8,IF(F9="TR",1,IF(F9="TEC",3,1))))) -> 70 | I9: =IF(F9="IPL","%pureza",IF(F9="RS","%rendimiento",IF(F9="VH","%humedad",IF(F9="TR","%retorno",IF(F9="TEC","%error","índice"))))) -> %rendimiento | J9: =IF(OR(F9="IPL",F9="RS",F9="Cpk_Mensual"),IF(G9<H9,"❌ ALERTA","✅ OK"),IF(G9>H9,"❌ ALERTA","✅ OK")) -> ✅ OK | K9: =IF(OR(F9="IPL",F9="RS",F9="Cpk_Mensual"),IF(G9<H9,"🔴 ALERTA",IF(G9<H9*1.05,"🟡 PRECAUCIÓN","🟢 OK")),IF(G9>H9,"🔴 ALERTA",IF(G9>H9*0.85,"🟡 PRECAUCIÓN","🟢 OK"))) -> 🟡 PRECAUCIÓN | L9: =IF(F9="IPL","Inspector de Calidad",IF(F9="RS","Coordinador de Planta",IF(F9="VH","Almacenista",IF(F9="TR","Gerente de Calidad",IF(F9="TEC","Supervisor","Ingeniero de Calidad"))))) -> Coordinador de Planta
A10: ="KPI-"&TEXT(ROW()-1,"000") -> KPI-009 | B10: =INDEX(Lotes!$B$2:$B$53,INT((ROW()-2)/6)+1) -> 46102 | C10: =INDEX(Lotes!$C$2:$C$53,INT((ROW()-2)/6)+1) -> 12 | D10: =INDEX(Lotes!$A$2:$A$53,INT((ROW()-2)/6)+1) -> RETEX-2024-002 | E10: =INDEX(Lotes!$D$2:$D$53,INT((ROW()-2)/6)+1) -> marzo | F10: VH | G10: 5.46 | H10: =IF(F10="IPL",96,IF(F10="RS",70,IF(F10="VH",8,IF(F10="TR",1,IF(F10="TEC",3,1))))) -> 8 | I10: =IF(F10="IPL","%pureza",IF(F10="RS","%rendimiento",IF(F10="VH","%humedad",IF(F10="TR","%retorno",IF(F10="TEC","%error","índice"))))) -> %humedad | J10: =IF(OR(F10="IPL",F10="RS",F10="Cpk_Mensual"),IF(G10<H10,"❌ ALERTA","✅ OK"),IF(G10>H10,"❌ ALERTA","✅ OK")) -> ✅ OK | K10: =IF(OR(F10="IPL",F10="RS",F10="Cpk_Mensual"),IF(G10<H10,"🔴 ALERTA",IF(G10<H10*1.05,"🟡 PRECAUCIÓN","🟢 OK")),IF(G10>H10,"🔴 ALERTA",IF(G10>H10*0.85,"🟡 PRECAUCIÓN","🟢 OK"))) -> 🟢 OK | L10: =IF(F10="IPL","Inspector de Calidad",IF(F10="RS","Coordinador de Planta",IF(F10="VH","Almacenista",IF(F10="TR","Gerente de Calidad",IF(F10="TEC","Supervisor","Ingeniero de Calidad"))))) -> Almacenista
A11: ="KPI-"&TEXT(ROW()-1,"000") -> KPI-010 | B11: =INDEX(Lotes!$B$2:$B$53,INT((ROW()-2)/6)+1) -> 46102 | C11: =INDEX(Lotes!$C$2:$C$53,INT((ROW()-2)/6)+1) -> 12 | D11: =INDEX(Lotes!$A$2:$A$53,INT((ROW()-2)/6)+1) -> RETEX-2024-002 | E11: =INDEX(Lotes!$D$2:$D$53,INT((ROW()-2)/6)+1) -> marzo | F11: TR | G11: 1.09 | H11: =IF(F11="IPL",96,IF(F11="RS",70,IF(F11="VH",8,IF(F11="TR",1,IF(F11="TEC",3,1))))) -> 1 | I11: =IF(F11="IPL","%pureza",IF(F11="RS","%rendimiento",IF(F11="VH","%humedad",IF(F11="TR","%retorno",IF(F11="TEC","%error","índice"))))) -> %retorno | J11: =IF(OR(F11="IPL",F11="RS",F11="Cpk_Mensual"),IF(G11<H11,"❌ ALERTA","✅ OK"),IF(G11>H11,"❌ ALERTA","✅ OK")) -> ❌ ALERTA | K11: =IF(OR(F11="IPL",F11="RS",F11="Cpk_Mensual"),IF(G11<H11,"🔴 ALERTA",IF(G11<H11*1.05,"🟡 PRECAUCIÓN","🟢 OK")),IF(G11>H11,"🔴 ALERTA",IF(G11>H11*0.85,"🟡 PRECAUCIÓN","🟢 OK"))) -> 🔴 ALERTA | L11: =IF(F11="IPL","Inspector de Calidad",IF(F11="RS","Coordinador de Planta",IF(F11="VH","Almacenista",IF(F11="TR","Gerente de Calidad",IF(F11="TEC","Supervisor","Ingeniero de Calidad"))))) -> Gerente de Calidad
A12: ="KPI-"&TEXT(ROW()-1,"000") -> KPI-011 | B12: =INDEX(Lotes!$B$2:$B$53,INT((ROW()-2)/6)+1) -> 46102 | C12: =INDEX(Lotes!$C$2:$C$53,INT((ROW()-2)/6)+1) -> 12 | D12: =INDEX(Lotes!$A$2:$A$53,INT((ROW()-2)/6)+1) -> RETEX-2024-002 | E12: =INDEX(Lotes!$D$2:$D$53,INT((ROW()-2)/6)+1) -> marzo | F12: TEC | G12: 1.88 | H12: =IF(F12="IPL",96,IF(F12="RS",70,IF(F12="VH",8,IF(F12="TR",1,IF(F12="TEC",3,1))))) -> 3 | I12: =IF(F12="IPL","%pureza",IF(F12="RS","%rendimiento",IF(F12="VH","%humedad",IF(F12="TR","%retorno",IF(F12="TEC","%error","índice"))))) -> %error | J12: =IF(OR(F12="IPL",F12="RS",F12="Cpk_Mensual"),IF(G12<H12,"❌ ALERTA","✅ OK"),IF(G12>H12,"❌ ALERTA","✅ OK")) -> ✅ OK | K12: =IF(OR(F12="IPL",F12="RS",F12="Cpk_Mensual"),IF(G12<H12,"🔴 ALERTA",IF(G12<H12*1.05,"🟡 PRECAUCIÓN","🟢 OK")),IF(G12>H12,"🔴 ALERTA",IF(G12>H12*0.85,"🟡 PRECAUCIÓN","🟢 OK"))) -> 🟢 OK | L12: =IF(F12="IPL","Inspector de Calidad",IF(F12="RS","Coordinador de Planta",IF(F12="VH","Almacenista",IF(F12="TR","Gerente de Calidad",IF(F12="TEC","Supervisor","Ingeniero de Calidad"))))) -> Supervisor
A13: ="KPI-"&TEXT(ROW()-1,"000") -> KPI-012 | B13: =INDEX(Lotes!$B$2:$B$53,INT((ROW()-2)/6)+1) -> 46102 | C13: =INDEX(Lotes!$C$2:$C$53,INT((ROW()-2)/6)+1) -> 12 | D13: =INDEX(Lotes!$A$2:$A$53,INT((ROW()-2)/6)+1) -> RETEX-2024-002 | E13: =INDEX(Lotes!$D$2:$D$53,INT((ROW()-2)/6)+1) -> marzo | F13: CPK_MENSUAL | G13: 0.99 | H13: =IF(F13="IPL",96,IF(F13="RS",70,IF(F13="VH",8,IF(F13="TR",1,IF(F13="TEC",3,1))))) -> 1 | I13: =IF(F13="IPL","%pureza",IF(F13="RS","%rendimiento",IF(F13="VH","%humedad",IF(F13="TR","%retorno",IF(F13="TEC","%error","índice"))))) -> índice | J13: =IF(OR(F13="IPL",F13="RS",F13="Cpk_Mensual"),IF(G13<H13,"❌ ALERTA","✅ OK"),IF(G13>H13,"❌ ALERTA","✅ OK")) -> ❌ ALERTA | K13: =IF(OR(F13="IPL",F13="RS",F13="Cpk_Mensual"),IF(G13<H13,"🔴 ALERTA",IF(G13<H13*1.05,"🟡 PRECAUCIÓN","🟢 OK")),IF(G13>H13,"🔴 ALERTA",IF(G13>H13*0.85,"🟡 PRECAUCIÓN","🟢 OK"))) -> 🔴 ALERTA | L13: =IF(F13="IPL","Inspector de Calidad",IF(F13="RS","Coordinador de Planta",IF(F13="VH","Almacenista",IF(F13="TR","Gerente de Calidad",IF(F13="TEC","Supervisor","Ingeniero de Calidad"))))) -> Ingeniero de Calidad
... A313: ="KPI-"&TEXT(ROW()-1,"000") -> KPI-312 | B313: =INDEX(Lotes!$B$2:$B$53,INT((ROW()-2)/6)+1) -> 46452 | C313: =INDEX(Lotes!$C$2:$C$53,INT((ROW()-2)/6)+1) -> 10 | D313: =INDEX(Lotes!$A$2:$A$53,INT((ROW()-2)/6)+1) -> RETEX-2024-052 | E313: =INDEX(Lotes!$D$2:$D$53,INT((ROW()-2)/6)+1) -> marzo | F313: CPK_MENSUAL | G313: 0.88 | H313: =IF(F313="IPL",96,IF(F313="RS",70,IF(F313="VH",8,IF(F313="TR",1,IF(F313="TEC",3,1))))) -> 1 | I313: =IF(F313="IPL","%pureza",IF(F313="RS","%rendimiento",IF(F313="VH","%humedad",IF(F313="TR","%retorno",IF(F313="TEC","%error","índice"))))) -> índice | J313: =IF(OR(F313="IPL",F313="RS",F313="Cpk_Mensual"),IF(G313<H313,"❌ ALERTA","✅ OK"),IF(G313>H313,"❌ ALERTA","✅ OK")) -> ❌ ALERTA | K313: =IF(OR(F313="IPL",F313="RS",F313="Cpk_Mensual"),IF(G313<H313,"🔴 ALERTA",IF(G313<H313*1.05,"🟡 PRECAUCIÓN","🟢 OK")),IF(G313>H313,"🔴 ALERTA",IF(G313>H313*0.85,"🟡 PRECAUCIÓN","🟢 OK"))) -> 🔴 ALERTA | L313: =IF(F313="IPL","Inspector de Calidad",IF(F313="RS","Coordinador de Planta",IF(F313="VH","Almacenista",IF(F313="TR","Gerente de Calidad",IF(F313="TEC","Supervisor","Ingeniero de Calidad"))))) -> Ingeniero de Calidad

Sheet Costos_CONC
A1: ID_Costo | B1: Mes_Num | C1: Mes_Nombre | D1: Categoria | E1: Monto_USD | F1: Porcentaje_Total | G1: Ahorro_Potencial_NIR | H1: CONC_Acumulado
A2: ="CONC-"&TEXT(ROW()-1,"000") -> CONC-001 | B2: =INT((ROW()-2)/4)+1 -> 1 | C2: =TEXT(DATE(2024,B2,1),"mmmm") -> enero | D2: Falla Interna | E2: 1440.73 | F2: =ROUND(E2/SUM($E$2:$E$49),4) -> 0.0435 | G2: =ROUND(IF(D2="Falla Interna",E2*0.8, IF(D2="Falla Externa",E2*0.9,IF(D2="Inspección",E2*1, 0))),2) -> 1152.58 | H2: =SUM($E$2:E2) -> 1440.73
A3: ="CONC-"&TEXT(ROW()-1,"000") -> CONC-002 | B3: =INT((ROW()-2)/4)+1 -> 1 | C3: =TEXT(DATE(2024,B3,1),"mmmm") -> enero | D3: Falla externa | E3: 730.48 | F3: =ROUND(E3/SUM($E$2:$E$49),4) -> 0.0221 | G3: =ROUND(IF(D3="Falla Interna",E3*0.8, IF(D3="Falla Externa",E3*0.9,IF(D3="Inspección",E3*1, 0))),2) -> 657.43 | H3: =SUM($E$2:E3) -> 2171.21
A4: ="CONC-"&TEXT(ROW()-1,"000") -> CONC-003 | B4: =INT((ROW()-2)/4)+1 -> 1 | C4: =TEXT(DATE(2024,B4,1),"mmmm") -> enero | D4: Inspección | E4: 374.12 | F4: =ROUND(E4/SUM($E$2:$E$49),4) -> 0.0113 | G4: =ROUND(IF(D4="Falla Interna",E4*0.8, IF(D4="Falla Externa",E4*0.9,IF(D4="Inspección",E4*1, 0))),2) -> 374.12 | H4: =SUM($E$2:E4) -> 2545.33
A5: ="CONC-"&TEXT(ROW()-1,"000") -> CONC-004 | B5: =INT((ROW()-2)/4)+1 -> 1 | C5: =TEXT(DATE(2024,B5,1),"mmmm") -> enero | D5: Prevención | E5: 250.77 | F5: =ROUND(E5/SUM($E$2:$E$49),4) -> 0.0076 | G5: =ROUND(IF(D5="Falla Interna",E5*0.8, IF(D5="Falla Externa",E5*0.9,IF(D5="Inspección",E5*1, 0))),2) -> 0 | H5: =SUM($E$2:E5) -> 2796.1
A6: ="CONC-"&TEXT(ROW()-1,"000") -> CONC-005 | B6: =INT((ROW()-2)/4)+1 -> 2 | C6: =TEXT(DATE(2024,B6,1),"mmmm") -> febrero | D6: Falla Interna | E6: 1333.11 | F6: =ROUND(E6/SUM($E$2:$E$49),4) -> 0.0403 | G6: =ROUND(IF(D6="Falla Interna",E6*0.8, IF(D6="Falla Externa",E6*0.9,IF(D6="Inspección",E6*1, 0))),2) -> 1066.49 | H6: =SUM($E$2:E6) -> 4129.21
A7: ="CONC-"&TEXT(ROW()-1,"000") -> CONC-006 | B7: =INT((ROW()-2)/4)+1 -> 2 | C7: =TEXT(DATE(2024,B7,1),"mmmm") -> febrero | D7: Falla externa | E7: 954.91 | F7: =ROUND(E7/SUM($E$2:$E$49),4) -> 0.0289 | G7: =ROUND(IF(D7="Falla Interna",E7*0.8, IF(D7="Falla Externa",E7*0.9,IF(D7="Inspección",E7*1, 0))),2) -> 859.42 | H7: =SUM($E$2:E7) -> 5084.12
A8: ="CONC-"&TEXT(ROW()-1,"000") -> CONC-007 | B8: =INT((ROW()-2)/4)+1 -> 2 | C8: =TEXT(DATE(2024,B8,1),"mmmm") -> febrero | D8: Inspección | E8: 490.92 | F8: =ROUND(E8/SUM($E$2:$E$49),4) -> 0.0148 | G8: =ROUND(IF(D8="Falla Interna",E8*0.8, IF(D8="Falla Externa",E8*0.9,IF(D8="Inspección",E8*1, 0))),2) -> 490.92 | H8: =SUM($E$2:E8) -> 5575.04
A9: ="CONC-"&TEXT(ROW()-1,"000") -> CONC-008 | B9: =INT((ROW()-2)/4)+1 -> 2 | C9: =TEXT(DATE(2024,B9,1),"mmmm") -> febrero | D9: Prevención | E9: 207.24 | F9: =ROUND(E9/SUM($E$2:$E$49),4) -> 0.0063 | G9: =ROUND(IF(D9="Falla Interna",E9*0.8, IF(D9="Falla Externa",E9*0.9,IF(D9="Inspección",E9*1, 0))),2) -> 0 | H9: =SUM($E$2:E9) -> 5782.28
A10: ="CONC-"&TEXT(ROW()-1,"000") -> CONC-009 | B10: =INT((ROW()-2)/4)+1 -> 3 | C10: =TEXT(DATE(2024,B10,1),"mmmm") -> marzo | D10: Falla Interna | E10: 1359.06 | F10: =ROUND(E10/SUM($E$2:$E$49),4) -> 0.0411 | G10: =ROUND(IF(D10="Falla Interna",E10*0.8, IF(D10="Falla Externa",E10*0.9,IF(D10="Inspección",E10*1, 0))),2) -> 1087.25 | H10: =SUM($E$2:E10) -> 7141.34
A11: ="CONC-"&TEXT(ROW()-1,"000") -> CONC-010 | B11: =INT((ROW()-2)/4)+1 -> 3 | C11: =TEXT(DATE(2024,B11,1),"mmmm") -> marzo | D11: Falla externa | E11: 991.5 | F11: =ROUND(E11/SUM($E$2:$E$49),4) -> 0.03 | G11: =ROUND(IF(D11="Falla Interna",E11*0.8, IF(D11="Falla Externa",E11*0.9,IF(D11="Inspección",E11*1, 0))),2) -> 892.35 | H11: =SUM($E$2:E11) -> 8132.84
A12: ="CONC-"&TEXT(ROW()-1,"000") -> CONC-011 | B12: =INT((ROW()-2)/4)+1 -> 3 | C12: =TEXT(DATE(2024,B12,1),"mmmm") -> marzo | D12: Inspección | E12: 442.49 | F12: =ROUND(E12/SUM($E$2:$E$49),4) -> 0.0134 | G12: =ROUND(IF(D12="Falla Interna",E12*0.8, IF(D12="Falla Externa",E12*0.9,IF(D12="Inspección",E12*1, 0))),2) -> 442.49 | H12: =SUM($E$2:E12) -> 8575.33
A13: ="CONC-"&TEXT(ROW()-1,"000") -> CONC-012 | B13: =INT((ROW()-2)/4)+1 -> 3 | C13: =TEXT(DATE(2024,B13,1),"mmmm") -> marzo | D13: Prevención | E13: 197.92 | F13: =ROUND(E13/SUM($E$2:$E$49),4) -> 0.006 | G13: =ROUND(IF(D13="Falla Interna",E13*0.8, IF(D13="Falla Externa",E13*0.9,IF(D13="Inspección",E13*1, 0))),2) -> 0 | H13: =SUM($E$2:E13) -> 8773.25
... A49: ="CONC-"&TEXT(ROW()-1,"000") -> CONC-048 | B49: =INT((ROW()-2)/4)+1 -> 12 | C49: =TEXT(DATE(2024,B49,1),"mmmm") -> diciembre | D49: Prevención | E49: 253.62 | F49: =ROUND(E49/SUM($E$2:$E$49),4) -> 0.0077 | G49: =ROUND(IF(D49="Falla Interna",E49*0.8, IF(D49="Falla Externa",E49*0.9,IF(D49="Inspección",E49*1, 0))),2) -> 0 | H49: =SUM($E$2:E49) -> 33086

Sheet Operadores
A1: ID_Operador | B1: Nombre | C1: Turno_Principal | D1: Nivel_Capacitacion | E1: Fecha_Ingreso | F1: Lotes_Asignados | G1: Promedio_Pureza | H1: Tasa_Error | I1: Evaluacion
A2: OP-01 | B2: Carlos Mendoza | C2: Matutino | D2: Avanzado | E2: 44635 | F2: =COUNTIF(Lotes!$G$2:$G$53,A2) -> 8 | G2: =IFERROR(AVERAGEIFS(Mediciones_Pureza!$F$2:$F$261,Mediciones_Pureza!$B$2:$B$261,INDEX(Lotes!$A$2:$A$53,MATCH(A2,Lotes!$G$2:$G$53,0))),"Sin datos") -> 98.14 | H2: =AVERAGEIFS(KPIs_Diarios!$G$2:$G$313,KPIs_Diarios!$F$2:$F$313,"TEC",KPIs_Diarios!$E$2:$E$313,INDEX(Lotes!$D$2:$D$53,MATCH(A2,Lotes!$G$2:$G$53,0))) -> 2.4775 | I2: =IF(D2="Avanzado", IF(H2<=2,"⭐ Excelente","✅ Bueno"), IF(D2="Intermedio",IF(H2<=2.5,"✅ Bueno","⚠️ Regular"), IF(H2<=3,"⚠️ Regular","❌ Requiere capacitación"))) -> ✅ Bueno
A3: OP-02 | B3: Maria López | C3: Vespertino | D3: Intermedio | E3: 44750 | F3: =COUNTIF(Lotes!$G$2:$G$53,A3) -> 6 | G3: =IFERROR(AVERAGEIFS(Mediciones_Pureza!$F$2:$F$261,Mediciones_Pureza!$B$2:$B$261,INDEX(Lotes!$A$2:$A$53,MATCH(A3,Lotes!$G$2:$G$53,0))),"Sin datos") -> 97.914 | H3: =AVERAGEIFS(KPIs_Diarios!$G$2:$G$313,KPIs_Diarios!$F$2:$F$313,"TEC",KPIs_Diarios!$E$2:$E$313,INDEX(Lotes!$D$2:$D$53,MATCH(A3,Lotes!$G$2:$G$53,0))) -> 2.6675 | I3: =IF(D3="Avanzado", IF(H3<=2,"⭐ Excelente","✅ Bueno"), IF(D3="Intermedio",IF(H3<=2.5,"✅ Bueno","⚠️ Regular"), IF(H3<=3,"⚠️ Regular","❌ Requiere capacitación"))) -> ⚠️ Regular
A4: OP-03 | B4: Juan Herrera | C4: Nocturno | D4: Básico | E4: 44938 | F4: =COUNTIF(Lotes!$G$2:$G$53,A4) -> 6 | G4: =IFERROR(AVERAGEIFS(Mediciones_Pureza!$F$2:$F$261,Mediciones_Pureza!$B$2:$B$261,INDEX(Lotes!$A$2:$A$53,MATCH(A4,Lotes!$G$2:$G$53,0))),"Sin datos") -> 97.464 | H4: =AVERAGEIFS(KPIs_Diarios!$G$2:$G$313,KPIs_Diarios!$F$2:$F$313,"TEC",KPIs_Diarios!$E$2:$E$313,INDEX(Lotes!$D$2:$D$53,MATCH(A4,Lotes!$G$2:$G$53,0))) -> 2.4 | I4: =IF(D4="Avanzado", IF(H4<=2,"⭐ Excelente","✅ Bueno"), IF(D4="Intermedio",IF(H4<=2.5,"✅ Bueno","⚠️ Regular"), IF(H4<=3,"⚠️ Regular","❌ Requiere capacitación"))) -> ⚠️ Regular
A5: OP-04 | B5: Ana Torres | C5: Matutino | D5: Intermedio | E5: 45036 | F5: =COUNTIF(Lotes!$G$2:$G$53,A5) -> 12 | G5: =IFERROR(AVERAGEIFS(Mediciones_Pureza!$F$2:$F$261,Mediciones_Pureza!$B$2:$B$261,INDEX(Lotes!$A$2:$A$53,MATCH(A5,Lotes!$G$2:$G$53,0))),"Sin datos") -> 98.914 | H5: =AVERAGEIFS(KPIs_Diarios!$G$2:$G$313,KPIs_Diarios!$F$2:$F$313,"TEC",KPIs_Diarios!$E$2:$E$313,INDEX(Lotes!$D$2:$D$53,MATCH(A5,Lotes!$G$2:$G$53,0))) -> 2.4 | I5: =IF(D5="Avanzado", IF(H5<=2,"⭐ Excelente","✅ Bueno"), IF(D5="Intermedio",IF(H5<=2.5,"✅ Bueno","⚠️ Regular"), IF(H5<=3,"⚠️ Regular","❌ Requiere capacitación"))) -> ✅ Bueno
A6: OP-05 | B6: Luis Ramirez | C6: Vespertino | D6: Avanzado | E6: 45174 | F6: =COUNTIF(Lotes!$G$2:$G$53,A6) -> 9 | G6: =IFERROR(AVERAGEIFS(Mediciones_Pureza!$F$2:$F$261,Mediciones_Pureza!$B$2:$B$261,INDEX(Lotes!$A$2:$A$53,MATCH(A6,Lotes!$G$2:$G$53,0))),"Sin datos") -> 98.102 | H6: =AVERAGEIFS(KPIs_Diarios!$G$2:$G$313,KPIs_Diarios!$F$2:$F$313,"TEC",KPIs_Diarios!$E$2:$E$313,INDEX(Lotes!$D$2:$D$53,MATCH(A6,Lotes!$G$2:$G$53,0))) -> 2.6675 | I6: =IF(D6="Avanzado", IF(H6<=2,"⭐ Excelente","✅ Bueno"), IF(D6="Intermedio",IF(H6<=2.5,"✅ Bueno","⚠️ Regular"), IF(H6<=3,"⚠️ Regular","❌ Requiere capacitación"))) -> ✅ Bueno
A7: OP-06 | B7: Sofia Castro | C7: Nocturno | D7: Básico | E7: 45248 | F7: =COUNTIF(Lotes!$G$2:$G$53,A7) -> 11 | G7: =IFERROR(AVERAGEIFS(Mediciones_Pureza!$F$2:$F$261,Mediciones_Pureza!$B$2:$B$261,INDEX(Lotes!$A$2:$A$53,MATCH(A7,Lotes!$G$2:$G$53,0))),"Sin datos") -> 98.602 | H7: =AVERAGEIFS(KPIs_Diarios!$G$2:$G$313,KPIs_Diarios!$F$2:$F$313,"TEC",KPIs_Diarios!$E$2:$E$313,INDEX(Lotes!$D$2:$D$53,MATCH(A7,Lotes!$G$2:$G$53,0))) -> 2.4 | I7: =IF(D7="Avanzado", IF(H7<=2,"⭐ Excelente","✅ Bueno"), IF(D7="Intermedio",IF(H7<=2.5,"✅ Bueno","⚠️ Regular"), IF(H7<=3,"⚠️ Regular","❌ Requiere capacitación"))) -> ⚠️ Regular

Sheet Resumen
B1: RETEX — Sistema de Gestión de Calidad
B2: ="Reporte generado: "&TEXT(TODAY(),"dd/mm/aaaa") -> Reporte generado: 16/03/2026 | F2: =IF(COUNTIF(Resumen!E8:E13,"🔴 ALERTA")>2,"🔴 SISTEMA EN ALERTA",IF(COUNTIF(Resumen!E8:E13,"🔴 ALERTA")>0,"🟡 REQUIERE ATENCIÓN","🟢 SISTEMA ESTABLE")) -> 🟢 SISTEMA ESTABLE
B5: KPI | C5: Valor Actual | D5: Umbral | E5: Semáforo | F5: Responsable
B8: IPL - Índice de Pureza por Lote | C8: =ROUND(AVERAGEIF(KPIs_Diarios!$F$2:$F$313,"IPL",KPIs_Diarios!$G$2:$G$313),2) -> 97.53 | D8: 0.96 | E8: =IF(C8<96,"ALERTA",IF(C8<96*1.05,"PRECAUCIÓN","OK")) -> PRECAUCIÓN | F8: Inspector de Calidad
B9: RS - Rendimiento de Selección | C9: =ROUND(AVERAGEIF(KPIs_Diarios!$F$2:$F$313,"RS",KPIs_Diarios!$G$2:$G$313),2) -> 72.29 | D9: 0.7 | E9: =IF(C9<70,"ALERTA",IF(C9<70*1.05,"PRECAUCIÓN","OK")) -> PRECAUCIÓN | F9: Coordinador de Planta
B10: VH - Verificación de Humedad | C10: =ROUND(AVERAGEIF(KPIs_Diarios!$F$2:$F$313,"VH",KPIs_Diarios!$G$2:$G$313),2) -> 6.24 | D10: 0.08 | E10: =IF(C10>8,"ALERTA",IF(C10>8*0.85,"PRECAUCIÓN","OK")) -> OK | F10: Almacenista
B11: TR - Tasa de Retorno | C11: =ROUND(AVERAGEIF(KPIs_Diarios!$F$2:$F$313,"TR",KPIs_Diarios!$G$2:$G$313),2) -> 0.78 | D11: 0.01 | E11: =IF(C11>1,"ALERTA",IF(C11>1*0.85,"PRECAUCIÓN","OK")) -> OK | F11: Gerente de calidad
B12: TEC - Tasa de ERROR en Clasificación | C12: =ROUND(AVERAGEIF(KPIs_Diarios!$F$2:$F$313,"TEC",KPIs_Diarios!$G$2:$G$313),2) -> 2.47 | D12: 0.03 | E12: =IF(C12>3,"ALERTA",IF(C12>3*0.85,"PRECAUCIÓN","OK")) -> OK | F12: Supervisor
B13: Cpk Mensual | C13: =ROUND(AVERAGEIF(KPIs_Diarios!$F$2:$F$313,"Cpk_Mensual",KPIs_Diarios!$G$2:$G$313),2) -> 0.9 | D13: 0.01 | E13: =IF(C13<1,"ALERTA",IF(C13<1.33,"PRECAUCIÓN","OK")) -> ALERTA | F13: Ingeniero de Calidad
B16: ANÁLISIS DE CAPACIDAD DEL PROCESO
B17: Media del proceso | C17: =ROUND(AVERAGE(Mediciones_Pureza!$F$2:$F$261),2) -> 98.23
B18: Sigma del proceso | C18: =ROUND(_xlfn.STDEV.P(Mediciones_Pureza!$F$2:$F$261),4) -> 0.7673
B19: Cp | C19: =ROUND((100-96)/(6*C18),2) -> 0.87
B20: Cpk | C20: =ROUND(MIN((100-C17)/(3*C18),(C17-96)/(3*C18)),2) -> 0.77
B21: Estado del proceso | C21: =IF(C20>=1.33,"CAPAZ",IF(C20>=1,"MARGINAL",IF(C20>=0.67,"NO CAPAZ — Requiere mejora","CRÍTICO"))) -> NO CAPAZ — Requiere mejora
B22: Lotes Inspeccionados | C22: =COUNTA(Mediciones_Pureza!$B$2:$B$261) -> 260
B23: Lotes NO OK | C23: =COUNTIF(Mediciones_Pureza!$J$2:$J$261,"❌*") -> 0
B24: Tasa de defectuosos | C24: =ROUND(C23/C22,4) -> 0
B27: ANÁLISIS DE COSTOS DE NO CALIDAD (CONC)
